[01/Aug/2016 18:34:50] ERROR [django.request:231] Internal Server Error: /curate/
Traceback (most recent call last):
  File "/home/NANOMINE/usr/local/lib/python2.7/site-packages/django/core/handlers/base.py", line 111, in get_response
    response = wrapped_callback(request, *callback_args, **callback_kwargs)
  File "/home/NANOMINE/Develop/mdcs/curate/views.py", line 66, in index
    return HttpResponse(template.render(context))
  File "/home/NANOMINE/usr/local/lib/python2.7/site-packages/django/template/base.py", line 148, in render
    return self._render(context)
  File "/home/NANOMINE/usr/local/lib/python2.7/site-packages/django/template/base.py", line 142, in _render
    return self.nodelist.render(context)
  File "/home/NANOMINE/usr/local/lib/python2.7/site-packages/django/template/base.py", line 844, in render
    bit = self.render_node(node, context)
  File "/home/NANOMINE/usr/local/lib/python2.7/site-packages/django/template/base.py", line 858, in render_node
    return node.render(context)
  File "/home/NANOMINE/usr/local/lib/python2.7/site-packages/django/template/loader_tags.py", line 104, in render
    compiled_parent = self.get_parent(context)
  File "/home/NANOMINE/usr/local/lib/python2.7/site-packages/django/template/loader_tags.py", line 101, in get_parent
    return get_template(parent)
  File "/home/NANOMINE/usr/local/lib/python2.7/site-packages/django/template/loader.py", line 144, in get_template
    template, origin = find_template(template_name, dirs)
  File "/home/NANOMINE/usr/local/lib/python2.7/site-packages/django/template/loader.py", line 132, in find_template
    source, display_name = loader(name, dirs)
  File "/home/NANOMINE/usr/local/lib/python2.7/site-packages/django/template/loader.py", line 44, in __call__
    return self.load_template(template_name, template_dirs)
  File "/home/NANOMINE/usr/local/lib/python2.7/site-packages/django/template/loader.py", line 50, in load_template
    template = get_template_from_string(source, origin, template_name)
  File "/home/NANOMINE/usr/local/lib/python2.7/site-packages/django/template/loader.py", line 156, in get_template_from_string
    return Template(source, origin, name)
  File "/home/NANOMINE/usr/local/lib/python2.7/site-packages/django/template/base.py", line 132, in __init__
    self.nodelist = compile_string(template_string, origin)
  File "/home/NANOMINE/usr/local/lib/python2.7/site-packages/django/template/base.py", line 162, in compile_string
    return parser.parse()
  File "/home/NANOMINE/usr/local/lib/python2.7/site-packages/django/template/base.py", line 290, in parse
    compiled_result = compile_func(self, token)
  File "/home/NANOMINE/usr/local/lib/python2.7/site-packages/django/template/loader_tags.py", line 201, in do_extends
    nodelist = parser.parse()
  File "/home/NANOMINE/usr/local/lib/python2.7/site-packages/django/template/base.py", line 290, in parse
    compiled_result = compile_func(self, token)
  File "/home/NANOMINE/usr/local/lib/python2.7/site-packages/django/template/loader_tags.py", line 175, in do_block
    nodelist = parser.parse(('endblock',))
  File "/home/NANOMINE/usr/local/lib/python2.7/site-packages/django/template/base.py", line 290, in parse
    compiled_result = compile_func(self, token)
  File "/home/NANOMINE/usr/local/lib/python2.7/site-packages/django/template/loader_tags.py", line 171, in do_block
    raise TemplateSyntaxError("'%s' tag with name '%s' appears more than once" % (bits[0], block_name))
TemplateSyntaxError: 'block' tag with name 'sidebar' appears more than once
[01/Aug/2016 19:11:01] WARNING [django.request:143] Not Found: /curate/save_data
[01/Aug/2016 19:12:48] DEBUG [oauthlib.oauth2.rfc6749.endpoints.resource:74] Dispatching token_type Bearer request to <oauthlib.oauth2.rfc6749.tokens.BearerToken object at 0x7fb6595dee10>.
[01/Aug/2016 19:12:50] DEBUG [oauthlib.oauth2.rfc6749.endpoints.resource:74] Dispatching token_type Bearer request to <oauthlib.oauth2.rfc6749.tokens.BearerToken object at 0x7fb6595ded10>.
[01/Aug/2016 19:12:53] DEBUG [oauthlib.oauth2.rfc6749.endpoints.resource:74] Dispatching token_type Bearer request to <oauthlib.oauth2.rfc6749.tokens.BearerToken object at 0x7fb6480521d0>.
[01/Aug/2016 19:12:55] DEBUG [oauthlib.oauth2.rfc6749.endpoints.resource:74] Dispatching token_type Bearer request to <oauthlib.oauth2.rfc6749.tokens.BearerToken object at 0x7fb64806e890>.
[01/Aug/2016 19:12:57] DEBUG [oauthlib.oauth2.rfc6749.endpoints.resource:74] Dispatching token_type Bearer request to <oauthlib.oauth2.rfc6749.tokens.BearerToken object at 0x7fb65a105890>.
[01/Aug/2016 19:12:59] DEBUG [oauthlib.oauth2.rfc6749.endpoints.resource:74] Dispatching token_type Bearer request to <oauthlib.oauth2.rfc6749.tokens.BearerToken object at 0x7fb64f751b90>.
[01/Aug/2016 19:13:22] DEBUG [oauthlib.oauth2.rfc6749.endpoints.resource:74] Dispatching token_type Bearer request to <oauthlib.oauth2.rfc6749.tokens.BearerToken object at 0x7fb658a0b990>.
[01/Aug/2016 19:13:24] DEBUG [oauthlib.oauth2.rfc6749.endpoints.resource:74] Dispatching token_type Bearer request to <oauthlib.oauth2.rfc6749.tokens.BearerToken object at 0x7fb658a5a490>.
[01/Aug/2016 19:13:28] DEBUG [oauthlib.oauth2.rfc6749.endpoints.resource:74] Dispatching token_type Bearer request to <oauthlib.oauth2.rfc6749.tokens.BearerToken object at 0x7fb658a0b790>.
[01/Aug/2016 19:13:46] DEBUG [oauthlib.oauth2.rfc6749.endpoints.resource:74] Dispatching token_type Bearer request to <oauthlib.oauth2.rfc6749.tokens.BearerToken object at 0x7fb65949ba50>.
[01/Aug/2016 19:13:49] DEBUG [oauthlib.oauth2.rfc6749.endpoints.resource:74] Dispatching token_type Bearer request to <oauthlib.oauth2.rfc6749.tokens.BearerToken object at 0x7fb65949b910>.
[01/Aug/2016 19:13:50] DEBUG [oauthlib.oauth2.rfc6749.endpoints.resource:74] Dispatching token_type Bearer request to <oauthlib.oauth2.rfc6749.tokens.BearerToken object at 0x7fb648065f50>.
[01/Aug/2016 19:14:15] DEBUG [oauthlib.oauth2.rfc6749.endpoints.resource:74] Dispatching token_type Bearer request to <oauthlib.oauth2.rfc6749.tokens.BearerToken object at 0x7fb64f751ad0>.
[01/Aug/2016 19:14:17] DEBUG [oauthlib.oauth2.rfc6749.endpoints.resource:74] Dispatching token_type Bearer request to <oauthlib.oauth2.rfc6749.tokens.BearerToken object at 0x7fb65949b650>.
[01/Aug/2016 19:14:19] DEBUG [oauthlib.oauth2.rfc6749.endpoints.resource:74] Dispatching token_type Bearer request to <oauthlib.oauth2.rfc6749.tokens.BearerToken object at 0x7fb6594ade50>.
[01/Aug/2016 19:27:59] ERROR [django.request:231] Internal Server Error: /modules/curator/blob-hoster
Traceback (most recent call last):
  File "/home/NANOMINE/usr/local/lib/python2.7/site-packages/django/core/handlers/base.py", line 111, in get_response
    response = wrapped_callback(request, *callback_args, **callback_kwargs)
  File "/home/NANOMINE/Develop/mdcs/modules/curator/views.py", line 4, in blob_hoster
    return BlobHosterModule().render(request)
  File "/home/NANOMINE/Develop/mdcs/modules/models.py", line 37, in render
    return self._post(request)
  File "/home/NANOMINE/Develop/mdcs/modules/models.py", line 82, in _post
    raise ModuleError('Something went wrong during module update: ' + e.message)
ModuleError: 'Something went wrong during module update: Data not properly sent to server. Please "file" in POST data.'
[01/Aug/2016 19:28:07] DEBUG [oauthlib.oauth2.rfc6749.endpoints.resource:74] Dispatching token_type Bearer request to <oauthlib.oauth2.rfc6749.tokens.BearerToken object at 0x7fb64d0d61d0>.
[01/Aug/2016 19:28:09] DEBUG [oauthlib.oauth2.rfc6749.endpoints.resource:74] Dispatching token_type Bearer request to <oauthlib.oauth2.rfc6749.tokens.BearerToken object at 0x7fb64d0d6c50>.
[01/Aug/2016 22:53:47] WARNING [django.request:143] Not Found: /favicon.ico
[01/Aug/2016 23:17:28] WARNING [django.request:143] Not Found: /robots.txt
[01/Aug/2016 23:17:28] WARNING [django.request:143] Not Found: /sitemap.xml
[02/Aug/2016 13:53:24] WARNING [django.request:143] Not Found: /favicon.ico
[02/Aug/2016 15:33:25] WARNING [django.request:143] Not Found: /apple-touch-icon-precomposed.png
[02/Aug/2016 15:33:25] WARNING [django.request:143] Not Found: /favicon.ico
[02/Aug/2016 15:33:26] WARNING [django.request:143] Not Found: /apple-touch-icon.png
[02/Aug/2016 15:33:27] WARNING [django.request:143] Not Found: /apple-touch-icon-precomposed.png
[02/Aug/2016 15:33:28] WARNING [django.request:143] Not Found: /apple-touch-icon.png
[02/Aug/2016 17:45:06] WARNING [django.request:143] Not Found: /favicon.ico
[02/Aug/2016 19:07:21] WARNING [django.request:143] Not Found: /apple-touch-icon-precomposed.png
[02/Aug/2016 19:07:21] WARNING [django.request:143] Not Found: /favicon.ico
[02/Aug/2016 19:07:21] WARNING [django.request:143] Not Found: /apple-touch-icon.png
[02/Aug/2016 19:21:49] WARNING [django.request:143] Not Found: /dashboard
[02/Aug/2016 20:17:50] WARNING [django.request:143] Not Found: /favicon.ico
[02/Aug/2016 23:57:47] WARNING [django.request:143] Not Found: /favicon.ico
[03/Aug/2016 03:17:39] WARNING [django.request:143] Not Found: /dashboard
[03/Aug/2016 03:17:41] WARNING [django.request:143] Not Found: /dashboard
[03/Aug/2016 14:48:44] WARNING [django.request:143] Not Found: /favicon.ico
[03/Aug/2016 15:28:20] WARNING [django.request:143] Not Found: /favicon.ico
[03/Aug/2016 18:19:19] WARNING [django.request:143] Not Found: /favicon.ico
[03/Aug/2016 19:11:43] WARNING [django.request:143] Not Found: /favicon.ico
[04/Aug/2016 00:55:23] WARNING [django.request:143] Not Found: /favicon.ico
[04/Aug/2016 00:58:30] WARNING [django.request:143] Not Found: /favicon.ico
[04/Aug/2016 00:58:30] WARNING [django.request:143] Not Found: /apple-touch-icon-precomposed.png
[04/Aug/2016 00:58:30] WARNING [django.request:143] Not Found: /apple-touch-icon.png
[04/Aug/2016 00:58:30] WARNING [django.request:143] Not Found: /apple-touch-icon-precomposed.png
[04/Aug/2016 00:58:30] WARNING [django.request:143] Not Found: /apple-touch-icon.png
[04/Aug/2016 01:21:35] WARNING [django.request:143] Not Found: /favicon.ico
