[26/Apr/2017 22:13:41] ERROR [django.request:256] Internal Server Error: /descchar/
Traceback (most recent call last):
  File "/home/NANOMINE/anaconda2/lib/python2.7/site-packages/django/core/handlers/base.py", line 132, in get_response
    response = wrapped_callback(request, *callback_args, **callback_kwargs)
  File "/home/NANOMINE/Develop/mdcs-v1.5_rc1/descchar/views.py", line 71, in home
    os.system('cp '+uploaded_file[0]+' '+ DocPath+'/'+str(run_id)+'.mat')
IndexError: list index out of range
[26/Apr/2017 22:14:08] ERROR [django.request:256] Internal Server Error: /descchar/
Traceback (most recent call last):
  File "/home/NANOMINE/anaconda2/lib/python2.7/site-packages/django/core/handlers/base.py", line 132, in get_response
    response = wrapped_callback(request, *callback_args, **callback_kwargs)
  File "/home/NANOMINE/Develop/mdcs-v1.5_rc1/descchar/views.py", line 71, in home
    os.system('cp '+uploaded_file[0]+' '+ DocPath+'/'+str(run_id)+'.mat')
IndexError: list index out of range
[26/Apr/2017 22:15:06] ERROR [django.request:256] Internal Server Error: /descchar/
Traceback (most recent call last):
  File "/home/NANOMINE/anaconda2/lib/python2.7/site-packages/django/core/handlers/base.py", line 132, in get_response
    response = wrapped_callback(request, *callback_args, **callback_kwargs)
  File "/home/NANOMINE/Develop/mdcs-v1.5_rc1/descchar/views.py", line 71, in home
    os.system('cp '+uploaded_file[0]+' '+ DocPath+'/'+str(run_id)+'.mat')
IndexError: list index out of range
[26/Apr/2017 22:19:25] DEBUG [paramiko.transport:282] starting thread (client mode): 0x6f69fcd0L
[26/Apr/2017 22:19:25] DEBUG [paramiko.transport:282] Local version/idstring: SSH-2.0-paramiko_2.1.2
[26/Apr/2017 22:19:25] DEBUG [paramiko.transport:282] Remote version/idstring: SSH-2.0-OpenSSH_6.6.1
[26/Apr/2017 22:19:25] INFO [paramiko.transport:282] Connected (version 2.0, client OpenSSH_6.6.1)
[26/Apr/2017 22:19:25] DEBUG [paramiko.transport:282] kex algos:[u'curve25519-sha256@libssh.org', u'ecdh-sha2-nistp256', u'ecdh-sha2-nistp384', u'ecdh-sha2-nistp521', u'diffie-hellman-group-exchange-sha256', u'diffie-hellman-group-exchange-sha1', u'diffie-hellman-group14-sha1', u'diffie-hellman-group1-sha1'] server key:[u'ssh-rsa', u'ecdsa-sha2-nistp256', u'ssh-ed25519'] client encrypt:[u'aes128-ctr', u'aes192-ctr', u'aes256-ctr', u'arcfour256', u'arcfour128', u'aes128-gcm@openssh.com', u'aes256-gcm@openssh.com', u'chacha20-poly1305@openssh.com', u'aes128-cbc', u'3des-cbc', u'blowfish-cbc', u'cast128-cbc', u'aes192-cbc', u'aes256-cbc', u'arcfour', u'rijndael-cbc@lysator.liu.se'] server encrypt:[u'aes128-ctr', u'aes192-ctr', u'aes256-ctr', u'arcfour256', u'arcfour128', u'aes128-gcm@openssh.com', u'aes256-gcm@openssh.com', u'chacha20-poly1305@openssh.com', u'aes128-cbc', u'3des-cbc', u'blowfish-cbc', u'cast128-cbc', u'aes192-cbc', u'aes256-cbc', u'arcfour', u'rijndael-cbc@lysator.liu.se'] client mac:[u'hmac-md5-etm@openssh.com', u'hmac-sha1-etm@openssh.com', u'umac-64-etm@openssh.com', u'umac-128-etm@openssh.com', u'hmac-sha2-256-etm@openssh.com', u'hmac-sha2-512-etm@openssh.com', u'hmac-ripemd160-etm@openssh.com', u'hmac-sha1-96-etm@openssh.com', u'hmac-md5-96-etm@openssh.com', u'hmac-md5', u'hmac-sha1', u'umac-64@openssh.com', u'umac-128@openssh.com', u'hmac-sha2-256', u'hmac-sha2-512', u'hmac-ripemd160', u'hmac-ripemd160@openssh.com', u'hmac-sha1-96', u'hmac-md5-96'] server mac:[u'hmac-md5-etm@openssh.com', u'hmac-sha1-etm@openssh.com', u'umac-64-etm@openssh.com', u'umac-128-etm@openssh.com', u'hmac-sha2-256-etm@openssh.com', u'hmac-sha2-512-etm@openssh.com', u'hmac-ripemd160-etm@openssh.com', u'hmac-sha1-96-etm@openssh.com', u'hmac-md5-96-etm@openssh.com', u'hmac-md5', u'hmac-sha1', u'umac-64@openssh.com', u'umac-128@openssh.com', u'hmac-sha2-256', u'hmac-sha2-512', u'hmac-ripemd160', u'hmac-ripemd160@openssh.com', u'hmac-sha1-96', u'hmac-md5-96'] client compress:[u'none', u'zlib@openssh.com'] server compress:[u'none', u'zlib@openssh.com'] client lang:[u''] server lang:[u''] kex follows?False
[26/Apr/2017 22:19:25] DEBUG [paramiko.transport:282] Kex agreed: diffie-hellman-group1-sha1
[26/Apr/2017 22:19:25] DEBUG [paramiko.transport:282] Cipher agreed: aes128-ctr
[26/Apr/2017 22:19:25] DEBUG [paramiko.transport:282] MAC agreed: hmac-sha2-256
[26/Apr/2017 22:19:25] DEBUG [paramiko.transport:282] Compression agreed: none
[26/Apr/2017 22:19:25] DEBUG [paramiko.transport:282] kex engine KexGroup1 specified hash_algo <built-in function openssl_sha1>
[26/Apr/2017 22:19:25] DEBUG [paramiko.transport:282] Switch to new keys ...
[26/Apr/2017 22:19:25] DEBUG [paramiko.transport:282] Adding ssh-rsa host key for 129.105.90.149: 3be932e37fd6c127bb6880a6ce0bab88
[26/Apr/2017 22:19:25] DEBUG [paramiko.transport:282] Trying discovered key 175016a8e15c3b3b3130d9f0396baec2 in /home/NANOMINE/.ssh/id_rsa
[26/Apr/2017 22:19:25] DEBUG [paramiko.transport:282] userauth is OK
[26/Apr/2017 22:19:25] INFO [paramiko.transport:282] Authentication (publickey) successful!
[26/Apr/2017 22:19:27] DEBUG [paramiko.transport:282] [chan 0] Max packet in: 32768 bytes
[26/Apr/2017 22:19:27] DEBUG [paramiko.transport:282] [chan 0] Max packet out: 32768 bytes
[26/Apr/2017 22:19:27] DEBUG [paramiko.transport:282] Secsh channel 0 opened.
[26/Apr/2017 22:19:27] DEBUG [paramiko.transport:282] [chan 0] Sesch channel 0 request ok
[26/Apr/2017 22:19:40] DEBUG [paramiko.transport:282] [chan 0] Unhandled channel request "exit-signal"
[26/Apr/2017 22:19:40] DEBUG [paramiko.transport:282] [chan 0] EOF received (0)
[26/Apr/2017 22:19:40] DEBUG [paramiko.transport:282] [chan 0] EOF sent (0)
[26/Apr/2017 22:20:39] DEBUG [paramiko.transport:282] EOF in transport thread
[26/Apr/2017 22:20:50] DEBUG [paramiko.transport:282] starting thread (client mode): 0xf542b810L
[26/Apr/2017 22:20:50] DEBUG [paramiko.transport:282] Local version/idstring: SSH-2.0-paramiko_2.1.2
[26/Apr/2017 22:20:50] DEBUG [paramiko.transport:282] Remote version/idstring: SSH-2.0-OpenSSH_6.6.1
[26/Apr/2017 22:20:50] INFO [paramiko.transport:282] Connected (version 2.0, client OpenSSH_6.6.1)
[26/Apr/2017 22:20:50] DEBUG [paramiko.transport:282] kex algos:[u'curve25519-sha256@libssh.org', u'ecdh-sha2-nistp256', u'ecdh-sha2-nistp384', u'ecdh-sha2-nistp521', u'diffie-hellman-group-exchange-sha256', u'diffie-hellman-group-exchange-sha1', u'diffie-hellman-group14-sha1', u'diffie-hellman-group1-sha1'] server key:[u'ssh-rsa', u'ecdsa-sha2-nistp256', u'ssh-ed25519'] client encrypt:[u'aes128-ctr', u'aes192-ctr', u'aes256-ctr', u'arcfour256', u'arcfour128', u'aes128-gcm@openssh.com', u'aes256-gcm@openssh.com', u'chacha20-poly1305@openssh.com', u'aes128-cbc', u'3des-cbc', u'blowfish-cbc', u'cast128-cbc', u'aes192-cbc', u'aes256-cbc', u'arcfour', u'rijndael-cbc@lysator.liu.se'] server encrypt:[u'aes128-ctr', u'aes192-ctr', u'aes256-ctr', u'arcfour256', u'arcfour128', u'aes128-gcm@openssh.com', u'aes256-gcm@openssh.com', u'chacha20-poly1305@openssh.com', u'aes128-cbc', u'3des-cbc', u'blowfish-cbc', u'cast128-cbc', u'aes192-cbc', u'aes256-cbc', u'arcfour', u'rijndael-cbc@lysator.liu.se'] client mac:[u'hmac-md5-etm@openssh.com', u'hmac-sha1-etm@openssh.com', u'umac-64-etm@openssh.com', u'umac-128-etm@openssh.com', u'hmac-sha2-256-etm@openssh.com', u'hmac-sha2-512-etm@openssh.com', u'hmac-ripemd160-etm@openssh.com', u'hmac-sha1-96-etm@openssh.com', u'hmac-md5-96-etm@openssh.com', u'hmac-md5', u'hmac-sha1', u'umac-64@openssh.com', u'umac-128@openssh.com', u'hmac-sha2-256', u'hmac-sha2-512', u'hmac-ripemd160', u'hmac-ripemd160@openssh.com', u'hmac-sha1-96', u'hmac-md5-96'] server mac:[u'hmac-md5-etm@openssh.com', u'hmac-sha1-etm@openssh.com', u'umac-64-etm@openssh.com', u'umac-128-etm@openssh.com', u'hmac-sha2-256-etm@openssh.com', u'hmac-sha2-512-etm@openssh.com', u'hmac-ripemd160-etm@openssh.com', u'hmac-sha1-96-etm@openssh.com', u'hmac-md5-96-etm@openssh.com', u'hmac-md5', u'hmac-sha1', u'umac-64@openssh.com', u'umac-128@openssh.com', u'hmac-sha2-256', u'hmac-sha2-512', u'hmac-ripemd160', u'hmac-ripemd160@openssh.com', u'hmac-sha1-96', u'hmac-md5-96'] client compress:[u'none', u'zlib@openssh.com'] server compress:[u'none', u'zlib@openssh.com'] client lang:[u''] server lang:[u''] kex follows?False
[26/Apr/2017 22:20:50] DEBUG [paramiko.transport:282] Kex agreed: diffie-hellman-group1-sha1
[26/Apr/2017 22:20:50] DEBUG [paramiko.transport:282] Cipher agreed: aes128-ctr
[26/Apr/2017 22:20:50] DEBUG [paramiko.transport:282] MAC agreed: hmac-sha2-256
[26/Apr/2017 22:20:50] DEBUG [paramiko.transport:282] Compression agreed: none
[26/Apr/2017 22:20:50] DEBUG [paramiko.transport:282] kex engine KexGroup1 specified hash_algo <built-in function openssl_sha1>
[26/Apr/2017 22:20:50] DEBUG [paramiko.transport:282] Switch to new keys ...
[26/Apr/2017 22:20:50] DEBUG [paramiko.transport:282] Adding ssh-rsa host key for 129.105.90.149: 3be932e37fd6c127bb6880a6ce0bab88
[26/Apr/2017 22:20:50] DEBUG [paramiko.transport:282] Trying discovered key 175016a8e15c3b3b3130d9f0396baec2 in /home/NANOMINE/.ssh/id_rsa
[26/Apr/2017 22:20:50] DEBUG [paramiko.transport:282] userauth is OK
[26/Apr/2017 22:20:51] INFO [paramiko.transport:282] Authentication (publickey) successful!
[26/Apr/2017 22:20:52] DEBUG [paramiko.transport:282] [chan 0] Max packet in: 32768 bytes
[26/Apr/2017 22:20:52] DEBUG [paramiko.transport:282] [chan 0] Max packet out: 32768 bytes
[26/Apr/2017 22:20:52] DEBUG [paramiko.transport:282] Secsh channel 0 opened.
[26/Apr/2017 22:20:52] DEBUG [paramiko.transport:282] [chan 0] Sesch channel 0 request ok
[26/Apr/2017 22:21:05] DEBUG [paramiko.transport:282] [chan 0] Unhandled channel request "exit-signal"
[26/Apr/2017 22:21:05] DEBUG [paramiko.transport:282] [chan 0] EOF received (0)
[26/Apr/2017 22:21:05] DEBUG [paramiko.transport:282] [chan 0] EOF sent (0)
[26/Apr/2017 22:21:31] DEBUG [paramiko.transport:282] EOF in transport thread
[26/Apr/2017 22:21:42] ERROR [django.request:256] Internal Server Error: /descchar/
Traceback (most recent call last):
  File "/home/NANOMINE/anaconda2/lib/python2.7/site-packages/django/core/handlers/base.py", line 132, in get_response
    response = wrapped_callback(request, *callback_args, **callback_kwargs)
  File "/home/NANOMINE/Develop/mdcs-v1.5_rc1/descchar/views.py", line 64, in home
    f.write(run_id+','+count[0], '\n')
TypeError: function takes exactly 1 argument (2 given)
[26/Apr/2017 22:21:59] DEBUG [paramiko.transport:282] starting thread (client mode): 0x16a0d810L
[26/Apr/2017 22:21:59] DEBUG [paramiko.transport:282] Local version/idstring: SSH-2.0-paramiko_2.1.2
[26/Apr/2017 22:21:59] DEBUG [paramiko.transport:282] Remote version/idstring: SSH-2.0-OpenSSH_6.6.1
[26/Apr/2017 22:21:59] INFO [paramiko.transport:282] Connected (version 2.0, client OpenSSH_6.6.1)
[26/Apr/2017 22:21:59] DEBUG [paramiko.transport:282] kex algos:[u'curve25519-sha256@libssh.org', u'ecdh-sha2-nistp256', u'ecdh-sha2-nistp384', u'ecdh-sha2-nistp521', u'diffie-hellman-group-exchange-sha256', u'diffie-hellman-group-exchange-sha1', u'diffie-hellman-group14-sha1', u'diffie-hellman-group1-sha1'] server key:[u'ssh-rsa', u'ecdsa-sha2-nistp256', u'ssh-ed25519'] client encrypt:[u'aes128-ctr', u'aes192-ctr', u'aes256-ctr', u'arcfour256', u'arcfour128', u'aes128-gcm@openssh.com', u'aes256-gcm@openssh.com', u'chacha20-poly1305@openssh.com', u'aes128-cbc', u'3des-cbc', u'blowfish-cbc', u'cast128-cbc', u'aes192-cbc', u'aes256-cbc', u'arcfour', u'rijndael-cbc@lysator.liu.se'] server encrypt:[u'aes128-ctr', u'aes192-ctr', u'aes256-ctr', u'arcfour256', u'arcfour128', u'aes128-gcm@openssh.com', u'aes256-gcm@openssh.com', u'chacha20-poly1305@openssh.com', u'aes128-cbc', u'3des-cbc', u'blowfish-cbc', u'cast128-cbc', u'aes192-cbc', u'aes256-cbc', u'arcfour', u'rijndael-cbc@lysator.liu.se'] client mac:[u'hmac-md5-etm@openssh.com', u'hmac-sha1-etm@openssh.com', u'umac-64-etm@openssh.com', u'umac-128-etm@openssh.com', u'hmac-sha2-256-etm@openssh.com', u'hmac-sha2-512-etm@openssh.com', u'hmac-ripemd160-etm@openssh.com', u'hmac-sha1-96-etm@openssh.com', u'hmac-md5-96-etm@openssh.com', u'hmac-md5', u'hmac-sha1', u'umac-64@openssh.com', u'umac-128@openssh.com', u'hmac-sha2-256', u'hmac-sha2-512', u'hmac-ripemd160', u'hmac-ripemd160@openssh.com', u'hmac-sha1-96', u'hmac-md5-96'] server mac:[u'hmac-md5-etm@openssh.com', u'hmac-sha1-etm@openssh.com', u'umac-64-etm@openssh.com', u'umac-128-etm@openssh.com', u'hmac-sha2-256-etm@openssh.com', u'hmac-sha2-512-etm@openssh.com', u'hmac-ripemd160-etm@openssh.com', u'hmac-sha1-96-etm@openssh.com', u'hmac-md5-96-etm@openssh.com', u'hmac-md5', u'hmac-sha1', u'umac-64@openssh.com', u'umac-128@openssh.com', u'hmac-sha2-256', u'hmac-sha2-512', u'hmac-ripemd160', u'hmac-ripemd160@openssh.com', u'hmac-sha1-96', u'hmac-md5-96'] client compress:[u'none', u'zlib@openssh.com'] server compress:[u'none', u'zlib@openssh.com'] client lang:[u''] server lang:[u''] kex follows?False
[26/Apr/2017 22:21:59] DEBUG [paramiko.transport:282] Kex agreed: diffie-hellman-group1-sha1
[26/Apr/2017 22:21:59] DEBUG [paramiko.transport:282] Cipher agreed: aes128-ctr
[26/Apr/2017 22:21:59] DEBUG [paramiko.transport:282] MAC agreed: hmac-sha2-256
[26/Apr/2017 22:21:59] DEBUG [paramiko.transport:282] Compression agreed: none
[26/Apr/2017 22:21:59] DEBUG [paramiko.transport:282] kex engine KexGroup1 specified hash_algo <built-in function openssl_sha1>
[26/Apr/2017 22:21:59] DEBUG [paramiko.transport:282] Switch to new keys ...
[26/Apr/2017 22:21:59] DEBUG [paramiko.transport:282] Adding ssh-rsa host key for 129.105.90.149: 3be932e37fd6c127bb6880a6ce0bab88
[26/Apr/2017 22:21:59] DEBUG [paramiko.transport:282] Trying discovered key 175016a8e15c3b3b3130d9f0396baec2 in /home/NANOMINE/.ssh/id_rsa
[26/Apr/2017 22:21:59] DEBUG [paramiko.transport:282] userauth is OK
[26/Apr/2017 22:21:59] INFO [paramiko.transport:282] Authentication (publickey) successful!
[26/Apr/2017 22:22:01] DEBUG [paramiko.transport:282] [chan 0] Max packet in: 32768 bytes
[26/Apr/2017 22:22:01] DEBUG [paramiko.transport:282] [chan 0] Max packet out: 32768 bytes
[26/Apr/2017 22:22:01] DEBUG [paramiko.transport:282] Secsh channel 0 opened.
[26/Apr/2017 22:22:01] DEBUG [paramiko.transport:282] [chan 0] Sesch channel 0 request ok
[26/Apr/2017 22:22:14] DEBUG [paramiko.transport:282] [chan 0] Unhandled channel request "exit-signal"
[26/Apr/2017 22:22:14] DEBUG [paramiko.transport:282] [chan 0] EOF received (0)
[26/Apr/2017 22:22:14] DEBUG [paramiko.transport:282] [chan 0] EOF sent (0)
[26/Apr/2017 22:22:26] ERROR [django.request:256] Internal Server Error: /descchar/
Traceback (most recent call last):
  File "/home/NANOMINE/anaconda2/lib/python2.7/site-packages/django/core/handlers/base.py", line 132, in get_response
    response = wrapped_callback(request, *callback_args, **callback_kwargs)
  File "/home/NANOMINE/Develop/mdcs-v1.5_rc1/descchar/views.py", line 71, in home
    os.system('cp '+uploaded_file[0]+' '+ DocPath+'/'+str(run_id)+'.mat')
IndexError: list index out of range
[26/Apr/2017 22:22:39] ERROR [django.request:256] Internal Server Error: /descchar/
Traceback (most recent call last):
  File "/home/NANOMINE/anaconda2/lib/python2.7/site-packages/django/core/handlers/base.py", line 132, in get_response
    response = wrapped_callback(request, *callback_args, **callback_kwargs)
  File "/home/NANOMINE/Develop/mdcs-v1.5_rc1/descchar/views.py", line 71, in home
    os.system('cp '+uploaded_file[0]+' '+ DocPath+'/'+str(run_id)+'.mat')
IndexError: list index out of range
[26/Apr/2017 22:23:24] ERROR [django.request:256] Internal Server Error: /descchar/
Traceback (most recent call last):
  File "/home/NANOMINE/anaconda2/lib/python2.7/site-packages/django/core/handlers/base.py", line 132, in get_response
    response = wrapped_callback(request, *callback_args, **callback_kwargs)
  File "/home/NANOMINE/Develop/mdcs-v1.5_rc1/descchar/views.py", line 71, in home
    os.system('cp '+uploaded_file[0]+' '+ DocPath+'/'+str(run_id)+'.mat')
IndexError: list index out of range
[26/Apr/2017 22:23:46] DEBUG [paramiko.transport:282] EOF in transport thread
[26/Apr/2017 22:24:02] DEBUG [paramiko.transport:282] starting thread (client mode): 0x650c1fd0L
[26/Apr/2017 22:24:02] DEBUG [paramiko.transport:282] Local version/idstring: SSH-2.0-paramiko_2.1.2
[26/Apr/2017 22:24:02] DEBUG [paramiko.transport:282] Remote version/idstring: SSH-2.0-OpenSSH_6.6.1
[26/Apr/2017 22:24:02] INFO [paramiko.transport:282] Connected (version 2.0, client OpenSSH_6.6.1)
[26/Apr/2017 22:24:02] DEBUG [paramiko.transport:282] kex algos:[u'curve25519-sha256@libssh.org', u'ecdh-sha2-nistp256', u'ecdh-sha2-nistp384', u'ecdh-sha2-nistp521', u'diffie-hellman-group-exchange-sha256', u'diffie-hellman-group-exchange-sha1', u'diffie-hellman-group14-sha1', u'diffie-hellman-group1-sha1'] server key:[u'ssh-rsa', u'ecdsa-sha2-nistp256', u'ssh-ed25519'] client encrypt:[u'aes128-ctr', u'aes192-ctr', u'aes256-ctr', u'arcfour256', u'arcfour128', u'aes128-gcm@openssh.com', u'aes256-gcm@openssh.com', u'chacha20-poly1305@openssh.com', u'aes128-cbc', u'3des-cbc', u'blowfish-cbc', u'cast128-cbc', u'aes192-cbc', u'aes256-cbc', u'arcfour', u'rijndael-cbc@lysator.liu.se'] server encrypt:[u'aes128-ctr', u'aes192-ctr', u'aes256-ctr', u'arcfour256', u'arcfour128', u'aes128-gcm@openssh.com', u'aes256-gcm@openssh.com', u'chacha20-poly1305@openssh.com', u'aes128-cbc', u'3des-cbc', u'blowfish-cbc', u'cast128-cbc', u'aes192-cbc', u'aes256-cbc', u'arcfour', u'rijndael-cbc@lysator.liu.se'] client mac:[u'hmac-md5-etm@openssh.com', u'hmac-sha1-etm@openssh.com', u'umac-64-etm@openssh.com', u'umac-128-etm@openssh.com', u'hmac-sha2-256-etm@openssh.com', u'hmac-sha2-512-etm@openssh.com', u'hmac-ripemd160-etm@openssh.com', u'hmac-sha1-96-etm@openssh.com', u'hmac-md5-96-etm@openssh.com', u'hmac-md5', u'hmac-sha1', u'umac-64@openssh.com', u'umac-128@openssh.com', u'hmac-sha2-256', u'hmac-sha2-512', u'hmac-ripemd160', u'hmac-ripemd160@openssh.com', u'hmac-sha1-96', u'hmac-md5-96'] server mac:[u'hmac-md5-etm@openssh.com', u'hmac-sha1-etm@openssh.com', u'umac-64-etm@openssh.com', u'umac-128-etm@openssh.com', u'hmac-sha2-256-etm@openssh.com', u'hmac-sha2-512-etm@openssh.com', u'hmac-ripemd160-etm@openssh.com', u'hmac-sha1-96-etm@openssh.com', u'hmac-md5-96-etm@openssh.com', u'hmac-md5', u'hmac-sha1', u'umac-64@openssh.com', u'umac-128@openssh.com', u'hmac-sha2-256', u'hmac-sha2-512', u'hmac-ripemd160', u'hmac-ripemd160@openssh.com', u'hmac-sha1-96', u'hmac-md5-96'] client compress:[u'none', u'zlib@openssh.com'] server compress:[u'none', u'zlib@openssh.com'] client lang:[u''] server lang:[u''] kex follows?False
[26/Apr/2017 22:24:02] DEBUG [paramiko.transport:282] Kex agreed: diffie-hellman-group1-sha1
[26/Apr/2017 22:24:02] DEBUG [paramiko.transport:282] Cipher agreed: aes128-ctr
[26/Apr/2017 22:24:02] DEBUG [paramiko.transport:282] MAC agreed: hmac-sha2-256
[26/Apr/2017 22:24:02] DEBUG [paramiko.transport:282] Compression agreed: none
[26/Apr/2017 22:24:02] DEBUG [paramiko.transport:282] kex engine KexGroup1 specified hash_algo <built-in function openssl_sha1>
[26/Apr/2017 22:24:02] DEBUG [paramiko.transport:282] Switch to new keys ...
[26/Apr/2017 22:24:02] DEBUG [paramiko.transport:282] Adding ssh-rsa host key for 129.105.90.149: 3be932e37fd6c127bb6880a6ce0bab88
[26/Apr/2017 22:24:02] DEBUG [paramiko.transport:282] Trying discovered key 175016a8e15c3b3b3130d9f0396baec2 in /home/NANOMINE/.ssh/id_rsa
[26/Apr/2017 22:24:02] DEBUG [paramiko.transport:282] userauth is OK
[26/Apr/2017 22:24:02] INFO [paramiko.transport:282] Authentication (publickey) successful!
[26/Apr/2017 22:24:04] DEBUG [paramiko.transport:282] [chan 0] Max packet in: 32768 bytes
[26/Apr/2017 22:24:04] DEBUG [paramiko.transport:282] [chan 0] Max packet out: 32768 bytes
[26/Apr/2017 22:24:04] DEBUG [paramiko.transport:282] Secsh channel 0 opened.
[26/Apr/2017 22:24:04] DEBUG [paramiko.transport:282] [chan 0] Sesch channel 0 request ok
[26/Apr/2017 22:24:16] DEBUG [paramiko.transport:282] [chan 0] Unhandled channel request "exit-signal"
[26/Apr/2017 22:24:16] DEBUG [paramiko.transport:282] [chan 0] EOF received (0)
[26/Apr/2017 22:24:16] DEBUG [paramiko.transport:282] [chan 0] EOF sent (0)
[26/Apr/2017 22:27:10] DEBUG [paramiko.transport:282] EOF in transport thread
[26/Apr/2017 22:32:22] ERROR [django.request:256] Internal Server Error: /descchar_view
Traceback (most recent call last):
  File "/home/NANOMINE/anaconda2/lib/python2.7/site-packages/django/core/handlers/base.py", line 132, in get_response
    response = wrapped_callback(request, *callback_args, **callback_kwargs)
  File "/home/NANOMINE/Develop/mdcs-v1.5_rc1/descchar/views.py", line 133, in check
    url_img = url_parent_server+run_id+'/image.jpg'
UnboundLocalError: local variable 'run_id' referenced before assignment
[26/Apr/2017 22:32:34] ERROR [django.request:256] Internal Server Error: /descchar_view
Traceback (most recent call last):
  File "/home/NANOMINE/anaconda2/lib/python2.7/site-packages/django/core/handlers/base.py", line 132, in get_response
    response = wrapped_callback(request, *callback_args, **callback_kwargs)
  File "/home/NANOMINE/Develop/mdcs-v1.5_rc1/descchar/views.py", line 152, in check
    'url_char': url_char_res,
UnboundLocalError: local variable 'url_char_res' referenced before assignment
[26/Apr/2017 22:33:04] ERROR [django.request:256] Internal Server Error: /descchar_view
Traceback (most recent call last):
  File "/home/NANOMINE/anaconda2/lib/python2.7/site-packages/django/core/handlers/base.py", line 132, in get_response
    response = wrapped_callback(request, *callback_args, **callback_kwargs)
  File "/home/NANOMINE/Develop/mdcs-v1.5_rc1/descchar/views.py", line 154, in check
    'job_id_num': count,
UnboundLocalError: local variable 'count' referenced before assignment
[26/Apr/2017 22:33:17] ERROR [django.request:256] Internal Server Error: /descchar_view
Traceback (most recent call last):
  File "/home/NANOMINE/anaconda2/lib/python2.7/site-packages/django/core/handlers/base.py", line 132, in get_response
    response = wrapped_callback(request, *callback_args, **callback_kwargs)
  File "/home/NANOMINE/Develop/mdcs-v1.5_rc1/descchar/views.py", line 154, in check
    'url_char': url_char_res,
UnboundLocalError: local variable 'count' referenced before assignment
[26/Apr/2017 22:33:40] ERROR [django.request:256] Internal Server Error: /descchar_view
Traceback (most recent call last):
  File "/home/NANOMINE/anaconda2/lib/python2.7/site-packages/django/core/handlers/base.py", line 132, in get_response
    response = wrapped_callback(request, *callback_args, **callback_kwargs)
  File "/home/NANOMINE/Develop/mdcs-v1.5_rc1/descchar/views.py", line 154, in check
    'url_char': url_char_res,
UnboundLocalError: local variable 'count' referenced before assignment
[26/Apr/2017 22:33:54] ERROR [django.request:256] Internal Server Error: /descchar_view
Traceback (most recent call last):
  File "/home/NANOMINE/anaconda2/lib/python2.7/site-packages/django/core/handlers/base.py", line 132, in get_response
    response = wrapped_callback(request, *callback_args, **callback_kwargs)
  File "/home/NANOMINE/Develop/mdcs-v1.5_rc1/descchar/views.py", line 140, in check
    mat = scipy.io.loadmat('/home/NANOMINE/nmdata/descchar/ch_result.mat'
  File "/home/NANOMINE/anaconda2/lib/python2.7/site-packages/scipy/io/matlab/mio.py", line 135, in loadmat
    MR = mat_reader_factory(file_name, appendmat, **kwargs)
  File "/home/NANOMINE/anaconda2/lib/python2.7/site-packages/scipy/io/matlab/mio.py", line 58, in mat_reader_factory
    byte_stream = _open_file(file_name, appendmat)
  File "/home/NANOMINE/anaconda2/lib/python2.7/site-packages/scipy/io/matlab/mio.py", line 23, in _open_file
    return open(file_like, 'rb')
IOError: [Errno 2] No such file or directory: '/home/NANOMINE/nmdata/descchar/ch_result.mat'
[26/Apr/2017 22:33:57] ERROR [django.request:256] Internal Server Error: /descchar_view
Traceback (most recent call last):
  File "/home/NANOMINE/anaconda2/lib/python2.7/site-packages/django/core/handlers/base.py", line 132, in get_response
    response = wrapped_callback(request, *callback_args, **callback_kwargs)
  File "/home/NANOMINE/Develop/mdcs-v1.5_rc1/descchar/views.py", line 140, in check
    mat = scipy.io.loadmat('/home/NANOMINE/nmdata/descchar/ch_result.mat'
  File "/home/NANOMINE/anaconda2/lib/python2.7/site-packages/scipy/io/matlab/mio.py", line 135, in loadmat
    MR = mat_reader_factory(file_name, appendmat, **kwargs)
  File "/home/NANOMINE/anaconda2/lib/python2.7/site-packages/scipy/io/matlab/mio.py", line 58, in mat_reader_factory
    byte_stream = _open_file(file_name, appendmat)
  File "/home/NANOMINE/anaconda2/lib/python2.7/site-packages/scipy/io/matlab/mio.py", line 23, in _open_file
    return open(file_like, 'rb')
IOError: [Errno 2] No such file or directory: '/home/NANOMINE/nmdata/descchar/ch_result.mat'
[26/Apr/2017 22:39:12] ERROR [django.request:256] Internal Server Error: /descchar_view
Traceback (most recent call last):
  File "/home/NANOMINE/anaconda2/lib/python2.7/site-packages/django/core/handlers/base.py", line 132, in get_response
    response = wrapped_callback(request, *callback_args, **callback_kwargs)
  File "/home/NANOMINE/Develop/mdcs-v1.5_rc1/descchar/views.py", line 135, in check
    url_img = url_parent_server+run_id+'/image.jpg'
UnboundLocalError: local variable 'run_id' referenced before assignment
[26/Apr/2017 22:39:21] ERROR [django.request:256] Internal Server Error: /descchar_view
Traceback (most recent call last):
  File "/home/NANOMINE/anaconda2/lib/python2.7/site-packages/django/core/handlers/base.py", line 132, in get_response
    response = wrapped_callback(request, *callback_args, **callback_kwargs)
  File "/home/NANOMINE/Develop/mdcs-v1.5_rc1/descchar/views.py", line 135, in check
    url_img = url_parent_server+run_id+'/image.jpg'
UnboundLocalError: local variable 'run_id' referenced before assignment
[26/Apr/2017 22:40:32] ERROR [django.request:256] Internal Server Error: /descchar_view
Traceback (most recent call last):
  File "/home/NANOMINE/anaconda2/lib/python2.7/site-packages/django/core/handlers/base.py", line 132, in get_response
    response = wrapped_callback(request, *callback_args, **callback_kwargs)
  File "/home/NANOMINE/Develop/mdcs-v1.5_rc1/descchar/views.py", line 135, in check
    
UnboundLocalError: local variable 'run_id' referenced before assignment
[26/Apr/2017 22:50:35] WARNING [django.request:170] Not Found: /stats_tool
[26/Apr/2017 22:58:02] WARNING [django.request:170] Not Found: /niblack
[26/Apr/2017 23:12:59] DEBUG [paramiko.transport:282] starting thread (client mode): 0xe9ea68d0L
[26/Apr/2017 23:12:59] DEBUG [paramiko.transport:282] Local version/idstring: SSH-2.0-paramiko_2.1.2
[26/Apr/2017 23:12:59] DEBUG [paramiko.transport:282] Remote version/idstring: SSH-2.0-OpenSSH_6.6.1
[26/Apr/2017 23:12:59] INFO [paramiko.transport:282] Connected (version 2.0, client OpenSSH_6.6.1)
[26/Apr/2017 23:12:59] DEBUG [paramiko.transport:282] kex algos:[u'curve25519-sha256@libssh.org', u'ecdh-sha2-nistp256', u'ecdh-sha2-nistp384', u'ecdh-sha2-nistp521', u'diffie-hellman-group-exchange-sha256', u'diffie-hellman-group-exchange-sha1', u'diffie-hellman-group14-sha1', u'diffie-hellman-group1-sha1'] server key:[u'ssh-rsa', u'ecdsa-sha2-nistp256', u'ssh-ed25519'] client encrypt:[u'aes128-ctr', u'aes192-ctr', u'aes256-ctr', u'arcfour256', u'arcfour128', u'aes128-gcm@openssh.com', u'aes256-gcm@openssh.com', u'chacha20-poly1305@openssh.com', u'aes128-cbc', u'3des-cbc', u'blowfish-cbc', u'cast128-cbc', u'aes192-cbc', u'aes256-cbc', u'arcfour', u'rijndael-cbc@lysator.liu.se'] server encrypt:[u'aes128-ctr', u'aes192-ctr', u'aes256-ctr', u'arcfour256', u'arcfour128', u'aes128-gcm@openssh.com', u'aes256-gcm@openssh.com', u'chacha20-poly1305@openssh.com', u'aes128-cbc', u'3des-cbc', u'blowfish-cbc', u'cast128-cbc', u'aes192-cbc', u'aes256-cbc', u'arcfour', u'rijndael-cbc@lysator.liu.se'] client mac:[u'hmac-md5-etm@openssh.com', u'hmac-sha1-etm@openssh.com', u'umac-64-etm@openssh.com', u'umac-128-etm@openssh.com', u'hmac-sha2-256-etm@openssh.com', u'hmac-sha2-512-etm@openssh.com', u'hmac-ripemd160-etm@openssh.com', u'hmac-sha1-96-etm@openssh.com', u'hmac-md5-96-etm@openssh.com', u'hmac-md5', u'hmac-sha1', u'umac-64@openssh.com', u'umac-128@openssh.com', u'hmac-sha2-256', u'hmac-sha2-512', u'hmac-ripemd160', u'hmac-ripemd160@openssh.com', u'hmac-sha1-96', u'hmac-md5-96'] server mac:[u'hmac-md5-etm@openssh.com', u'hmac-sha1-etm@openssh.com', u'umac-64-etm@openssh.com', u'umac-128-etm@openssh.com', u'hmac-sha2-256-etm@openssh.com', u'hmac-sha2-512-etm@openssh.com', u'hmac-ripemd160-etm@openssh.com', u'hmac-sha1-96-etm@openssh.com', u'hmac-md5-96-etm@openssh.com', u'hmac-md5', u'hmac-sha1', u'umac-64@openssh.com', u'umac-128@openssh.com', u'hmac-sha2-256', u'hmac-sha2-512', u'hmac-ripemd160', u'hmac-ripemd160@openssh.com', u'hmac-sha1-96', u'hmac-md5-96'] client compress:[u'none', u'zlib@openssh.com'] server compress:[u'none', u'zlib@openssh.com'] client lang:[u''] server lang:[u''] kex follows?False
[26/Apr/2017 23:12:59] DEBUG [paramiko.transport:282] Kex agreed: diffie-hellman-group1-sha1
[26/Apr/2017 23:12:59] DEBUG [paramiko.transport:282] Cipher agreed: aes128-ctr
[26/Apr/2017 23:12:59] DEBUG [paramiko.transport:282] MAC agreed: hmac-sha2-256
[26/Apr/2017 23:12:59] DEBUG [paramiko.transport:282] Compression agreed: none
[26/Apr/2017 23:12:59] DEBUG [paramiko.transport:282] kex engine KexGroup1 specified hash_algo <built-in function openssl_sha1>
[26/Apr/2017 23:12:59] DEBUG [paramiko.transport:282] Switch to new keys ...
[26/Apr/2017 23:12:59] DEBUG [paramiko.transport:282] Adding ssh-rsa host key for 129.105.90.149: 3be932e37fd6c127bb6880a6ce0bab88
[26/Apr/2017 23:12:59] DEBUG [paramiko.transport:282] Trying discovered key 175016a8e15c3b3b3130d9f0396baec2 in /home/NANOMINE/.ssh/id_rsa
[26/Apr/2017 23:12:59] DEBUG [paramiko.transport:282] userauth is OK
[26/Apr/2017 23:12:59] INFO [paramiko.transport:282] Authentication (publickey) successful!
[26/Apr/2017 23:13:01] DEBUG [paramiko.transport:282] [chan 0] Max packet in: 32768 bytes
[26/Apr/2017 23:13:01] DEBUG [paramiko.transport:282] [chan 0] Max packet out: 32768 bytes
[26/Apr/2017 23:13:01] DEBUG [paramiko.transport:282] Secsh channel 0 opened.
[26/Apr/2017 23:13:01] DEBUG [paramiko.transport:282] [chan 0] Sesch channel 0 request ok
[26/Apr/2017 23:13:11] ERROR [django.request:256] Internal Server Error: /descchar_view
Traceback (most recent call last):
  File "/home/NANOMINE/anaconda2/lib/python2.7/site-packages/django/core/handlers/base.py", line 132, in get_response
    response = wrapped_callback(request, *callback_args, **callback_kwargs)
  File "/home/NANOMINE/Develop/mdcs-v1.5_rc1/descchar/views.py", line 160, in check
    'job_id_num': run_id,
UnboundLocalError: local variable 'run_id' referenced before assignment
[26/Apr/2017 23:13:14] DEBUG [paramiko.transport:282] [chan 0] Unhandled channel request "exit-signal"
[26/Apr/2017 23:13:14] DEBUG [paramiko.transport:282] [chan 0] EOF received (0)
[26/Apr/2017 23:13:14] DEBUG [paramiko.transport:282] [chan 0] EOF sent (0)
[26/Apr/2017 23:13:16] ERROR [django.request:256] Internal Server Error: /descchar_view
Traceback (most recent call last):
  File "/home/NANOMINE/anaconda2/lib/python2.7/site-packages/django/core/handlers/base.py", line 132, in get_response
    response = wrapped_callback(request, *callback_args, **callback_kwargs)
  File "/home/NANOMINE/Develop/mdcs-v1.5_rc1/descchar/views.py", line 160, in check
    'job_id_num': run_id,
UnboundLocalError: local variable 'run_id' referenced before assignment
[26/Apr/2017 23:13:17] ERROR [django.request:256] Internal Server Error: /descchar_view
Traceback (most recent call last):
  File "/home/NANOMINE/anaconda2/lib/python2.7/site-packages/django/core/handlers/base.py", line 132, in get_response
    response = wrapped_callback(request, *callback_args, **callback_kwargs)
  File "/home/NANOMINE/Develop/mdcs-v1.5_rc1/descchar/views.py", line 160, in check
    'job_id_num': run_id,
UnboundLocalError: local variable 'run_id' referenced before assignment
[26/Apr/2017 23:14:08] DEBUG [paramiko.transport:282] EOF in transport thread
[27/Apr/2017 01:16:23] WARNING [django.request:170] Not Found: /http:/www.baidu.com/cache/global/img/gs.gif
[27/Apr/2017 11:15:46] DEBUG [paramiko.transport:282] starting thread (client mode): 0x22a00610L
[27/Apr/2017 11:15:46] DEBUG [paramiko.transport:282] Local version/idstring: SSH-2.0-paramiko_2.1.2
[27/Apr/2017 11:15:46] DEBUG [paramiko.transport:282] Remote version/idstring: SSH-2.0-OpenSSH_6.6.1
[27/Apr/2017 11:15:46] INFO [paramiko.transport:282] Connected (version 2.0, client OpenSSH_6.6.1)
[27/Apr/2017 11:15:46] DEBUG [paramiko.transport:282] kex algos:[u'curve25519-sha256@libssh.org', u'ecdh-sha2-nistp256', u'ecdh-sha2-nistp384', u'ecdh-sha2-nistp521', u'diffie-hellman-group-exchange-sha256', u'diffie-hellman-group-exchange-sha1', u'diffie-hellman-group14-sha1', u'diffie-hellman-group1-sha1'] server key:[u'ssh-rsa', u'ecdsa-sha2-nistp256', u'ssh-ed25519'] client encrypt:[u'aes128-ctr', u'aes192-ctr', u'aes256-ctr', u'arcfour256', u'arcfour128', u'aes128-gcm@openssh.com', u'aes256-gcm@openssh.com', u'chacha20-poly1305@openssh.com', u'aes128-cbc', u'3des-cbc', u'blowfish-cbc', u'cast128-cbc', u'aes192-cbc', u'aes256-cbc', u'arcfour', u'rijndael-cbc@lysator.liu.se'] server encrypt:[u'aes128-ctr', u'aes192-ctr', u'aes256-ctr', u'arcfour256', u'arcfour128', u'aes128-gcm@openssh.com', u'aes256-gcm@openssh.com', u'chacha20-poly1305@openssh.com', u'aes128-cbc', u'3des-cbc', u'blowfish-cbc', u'cast128-cbc', u'aes192-cbc', u'aes256-cbc', u'arcfour', u'rijndael-cbc@lysator.liu.se'] client mac:[u'hmac-md5-etm@openssh.com', u'hmac-sha1-etm@openssh.com', u'umac-64-etm@openssh.com', u'umac-128-etm@openssh.com', u'hmac-sha2-256-etm@openssh.com', u'hmac-sha2-512-etm@openssh.com', u'hmac-ripemd160-etm@openssh.com', u'hmac-sha1-96-etm@openssh.com', u'hmac-md5-96-etm@openssh.com', u'hmac-md5', u'hmac-sha1', u'umac-64@openssh.com', u'umac-128@openssh.com', u'hmac-sha2-256', u'hmac-sha2-512', u'hmac-ripemd160', u'hmac-ripemd160@openssh.com', u'hmac-sha1-96', u'hmac-md5-96'] server mac:[u'hmac-md5-etm@openssh.com', u'hmac-sha1-etm@openssh.com', u'umac-64-etm@openssh.com', u'umac-128-etm@openssh.com', u'hmac-sha2-256-etm@openssh.com', u'hmac-sha2-512-etm@openssh.com', u'hmac-ripemd160-etm@openssh.com', u'hmac-sha1-96-etm@openssh.com', u'hmac-md5-96-etm@openssh.com', u'hmac-md5', u'hmac-sha1', u'umac-64@openssh.com', u'umac-128@openssh.com', u'hmac-sha2-256', u'hmac-sha2-512', u'hmac-ripemd160', u'hmac-ripemd160@openssh.com', u'hmac-sha1-96', u'hmac-md5-96'] client compress:[u'none', u'zlib@openssh.com'] server compress:[u'none', u'zlib@openssh.com'] client lang:[u''] server lang:[u''] kex follows?False
[27/Apr/2017 11:15:46] DEBUG [paramiko.transport:282] Kex agreed: diffie-hellman-group1-sha1
[27/Apr/2017 11:15:46] DEBUG [paramiko.transport:282] Cipher agreed: aes128-ctr
[27/Apr/2017 11:15:46] DEBUG [paramiko.transport:282] MAC agreed: hmac-sha2-256
[27/Apr/2017 11:15:46] DEBUG [paramiko.transport:282] Compression agreed: none
[27/Apr/2017 11:15:46] DEBUG [paramiko.transport:282] kex engine KexGroup1 specified hash_algo <built-in function openssl_sha1>
[27/Apr/2017 11:15:46] DEBUG [paramiko.transport:282] Switch to new keys ...
[27/Apr/2017 11:15:46] DEBUG [paramiko.transport:282] Adding ssh-rsa host key for 129.105.90.149: 3be932e37fd6c127bb6880a6ce0bab88
[27/Apr/2017 11:15:46] DEBUG [paramiko.transport:282] Trying discovered key 175016a8e15c3b3b3130d9f0396baec2 in /home/NANOMINE/.ssh/id_rsa
[27/Apr/2017 11:15:46] DEBUG [paramiko.transport:282] userauth is OK
[27/Apr/2017 11:15:46] INFO [paramiko.transport:282] Authentication (publickey) successful!
[27/Apr/2017 11:15:48] DEBUG [paramiko.transport:282] [chan 0] Max packet in: 32768 bytes
[27/Apr/2017 11:15:48] DEBUG [paramiko.transport:282] [chan 0] Max packet out: 32768 bytes
[27/Apr/2017 11:15:48] DEBUG [paramiko.transport:282] Secsh channel 0 opened.
[27/Apr/2017 11:15:48] DEBUG [paramiko.transport:282] [chan 0] Sesch channel 0 request ok
[27/Apr/2017 11:16:01] DEBUG [paramiko.transport:282] [chan 0] Unhandled channel request "exit-signal"
[27/Apr/2017 11:16:01] DEBUG [paramiko.transport:282] [chan 0] EOF received (0)
[27/Apr/2017 11:16:01] DEBUG [paramiko.transport:282] [chan 0] EOF sent (0)
[27/Apr/2017 11:17:23] WARNING [django.request:170] Not Found: /FEA2D
[27/Apr/2017 11:22:01] DEBUG [paramiko.transport:282] EOF in transport thread
[27/Apr/2017 11:26:07] ERROR [django.request:256] Internal Server Error: /dynamfit
Traceback (most recent call last):
  File "/home/NANOMINE/anaconda2/lib/python2.7/site-packages/django/core/handlers/base.py", line 108, in get_response
    response = middleware_method(request)
  File "/home/NANOMINE/anaconda2/lib/python2.7/site-packages/django/middleware/common.py", line 75, in process_request
    urlresolvers.is_valid_path("%s/" % request.path_info, urlconf)):
  File "/home/NANOMINE/anaconda2/lib/python2.7/site-packages/django/core/urlresolvers.py", line 646, in is_valid_path
    resolve(path, urlconf)
  File "/home/NANOMINE/anaconda2/lib/python2.7/site-packages/django/core/urlresolvers.py", line 521, in resolve
    return get_resolver(urlconf).resolve(path)
  File "/home/NANOMINE/anaconda2/lib/python2.7/site-packages/django/core/urlresolvers.py", line 367, in resolve
    sub_match = pattern.resolve(new_path)
  File "/home/NANOMINE/anaconda2/lib/python2.7/site-packages/django/core/urlresolvers.py", line 239, in resolve
    return ResolverMatch(self.callback, args, kwargs, self.name)
  File "/home/NANOMINE/anaconda2/lib/python2.7/site-packages/django/core/urlresolvers.py", line 246, in callback
    self._callback = get_callable(self._callback_str)
  File "/home/NANOMINE/anaconda2/lib/python2.7/site-packages/django/utils/lru_cache.py", line 101, in wrapper
    result = user_function(*args, **kwds)
  File "/home/NANOMINE/anaconda2/lib/python2.7/site-packages/django/core/urlresolvers.py", line 105, in get_callable
    mod = import_module(mod_name)
  File "/home/NANOMINE/anaconda2/lib/python2.7/importlib/__init__.py", line 37, in import_module
    __import__(name)
  File "/home/NANOMINE/Develop/mdcs-v1.5_rc1/dynamfit/views.py", line 5, in <module>
    from .forms import *
ImportError: No module named forms
[27/Apr/2017 11:27:51] ERROR [django.request:256] Internal Server Error: /dynamfit
Traceback (most recent call last):
  File "/home/NANOMINE/anaconda2/lib/python2.7/site-packages/django/core/handlers/base.py", line 108, in get_response
    response = middleware_method(request)
  File "/home/NANOMINE/anaconda2/lib/python2.7/site-packages/django/middleware/common.py", line 75, in process_request
    urlresolvers.is_valid_path("%s/" % request.path_info, urlconf)):
  File "/home/NANOMINE/anaconda2/lib/python2.7/site-packages/django/core/urlresolvers.py", line 646, in is_valid_path
    resolve(path, urlconf)
  File "/home/NANOMINE/anaconda2/lib/python2.7/site-packages/django/core/urlresolvers.py", line 521, in resolve
    return get_resolver(urlconf).resolve(path)
  File "/home/NANOMINE/anaconda2/lib/python2.7/site-packages/django/core/urlresolvers.py", line 367, in resolve
    sub_match = pattern.resolve(new_path)
  File "/home/NANOMINE/anaconda2/lib/python2.7/site-packages/django/core/urlresolvers.py", line 239, in resolve
    return ResolverMatch(self.callback, args, kwargs, self.name)
  File "/home/NANOMINE/anaconda2/lib/python2.7/site-packages/django/core/urlresolvers.py", line 246, in callback
    self._callback = get_callable(self._callback_str)
  File "/home/NANOMINE/anaconda2/lib/python2.7/site-packages/django/utils/lru_cache.py", line 101, in wrapper
    result = user_function(*args, **kwds)
  File "/home/NANOMINE/anaconda2/lib/python2.7/site-packages/django/core/urlresolvers.py", line 105, in get_callable
    mod = import_module(mod_name)
  File "/home/NANOMINE/anaconda2/lib/python2.7/importlib/__init__.py", line 37, in import_module
    __import__(name)
  File "/home/NANOMINE/Develop/mdcs-v1.5_rc1/dynamfit/views.py", line 8, in <module>
    from Dynamfit.models import Document
ImportError: No module named Dynamfit.models
[27/Apr/2017 11:28:11] ERROR [django.request:256] Internal Server Error: /dynamfit/
Traceback (most recent call last):
  File "/home/NANOMINE/anaconda2/lib/python2.7/site-packages/django/core/handlers/base.py", line 132, in get_response
    response = wrapped_callback(request, *callback_args, **callback_kwargs)
  File "/home/NANOMINE/Develop/mdcs-v1.5_rc1/dynamfit/views.py", line 120, in home
    context_instance=RequestContext(request))
  File "/home/NANOMINE/anaconda2/lib/python2.7/site-packages/django/shortcuts.py", line 89, in render
    using=using)
  File "/home/NANOMINE/anaconda2/lib/python2.7/site-packages/django/template/loader.py", line 137, in render_to_string
    raise TemplateDoesNotExist(template_name)
TemplateDoesNotExist: Dynamfit_new.html
[27/Apr/2017 11:29:30] ERROR [django.request:256] Internal Server Error: /dynamfit/
Traceback (most recent call last):
  File "/home/NANOMINE/anaconda2/lib/python2.7/site-packages/django/core/handlers/base.py", line 132, in get_response
    response = wrapped_callback(request, *callback_args, **callback_kwargs)
  File "/home/NANOMINE/Develop/mdcs-v1.5_rc1/dynamfit/views.py", line 120, in home
    def runmodel(request):
  File "/home/NANOMINE/anaconda2/lib/python2.7/site-packages/django/shortcuts.py", line 89, in render
    using=using)
  File "/home/NANOMINE/anaconda2/lib/python2.7/site-packages/django/template/loader.py", line 137, in render_to_string
    raise TemplateDoesNotExist(template_name)
TemplateDoesNotExist: Dynamfit_new.html
[27/Apr/2017 11:30:03] ERROR [django.request:256] Internal Server Error: /dynamfit/
Traceback (most recent call last):
  File "/home/NANOMINE/anaconda2/lib/python2.7/site-packages/django/core/handlers/base.py", line 132, in get_response
    response = wrapped_callback(request, *callback_args, **callback_kwargs)
  File "/home/NANOMINE/Develop/mdcs-v1.5_rc1/dynamfit/views.py", line 120, in home
    def runmodel(request):
  File "/home/NANOMINE/anaconda2/lib/python2.7/site-packages/django/shortcuts.py", line 89, in render
    using=using)
  File "/home/NANOMINE/anaconda2/lib/python2.7/site-packages/django/template/loader.py", line 137, in render_to_string
    raise TemplateDoesNotExist(template_name)
TemplateDoesNotExist: Dynamfit_new.html
[27/Apr/2017 11:30:09] ERROR [django.request:256] Internal Server Error: /dynamfit/
Traceback (most recent call last):
  File "/home/NANOMINE/anaconda2/lib/python2.7/site-packages/django/core/handlers/base.py", line 132, in get_response
    response = wrapped_callback(request, *callback_args, **callback_kwargs)
  File "/home/NANOMINE/Develop/mdcs-v1.5_rc1/dynamfit/views.py", line 116, in home
    context_instance=RequestContext(request))
  File "/home/NANOMINE/anaconda2/lib/python2.7/site-packages/django/shortcuts.py", line 89, in render
    using=using)
  File "/home/NANOMINE/anaconda2/lib/python2.7/site-packages/django/template/loader.py", line 137, in render_to_string
    raise TemplateDoesNotExist(template_name)
TemplateDoesNotExist: Dynamfit_new.html
[27/Apr/2017 11:31:02] ERROR [django.request:256] Internal Server Error: /dynamfit/
Traceback (most recent call last):
  File "/home/NANOMINE/anaconda2/lib/python2.7/site-packages/django/core/handlers/base.py", line 132, in get_response
    response = wrapped_callback(request, *callback_args, **callback_kwargs)
  File "/home/NANOMINE/Develop/mdcs-v1.5_rc1/dynamfit/views.py", line 116, in home
    context_instance=RequestContext(request))
  File "/home/NANOMINE/anaconda2/lib/python2.7/site-packages/django/shortcuts.py", line 89, in render
    using=using)
  File "/home/NANOMINE/anaconda2/lib/python2.7/site-packages/django/template/loader.py", line 137, in render_to_string
    raise TemplateDoesNotExist(template_name)
TemplateDoesNotExist: Dynamfit_new.html
[27/Apr/2017 11:47:11] ERROR [django.request:256] Internal Server Error: /DynamfitExample
Traceback (most recent call last):
  File "/home/NANOMINE/anaconda2/lib/python2.7/site-packages/django/core/handlers/base.py", line 132, in get_response
    response = wrapped_callback(request, *callback_args, **callback_kwargs)
  File "/home/NANOMINE/Develop/mdcs-v1.5_rc1/dynamfit/views.py", line 140, in sample
    return redirect('/login')
  File "/home/NANOMINE/anaconda2/lib/python2.7/site-packages/django/shortcuts.py", line 45, in render_to_response
    using=using)
  File "/home/NANOMINE/anaconda2/lib/python2.7/site-packages/django/template/loader.py", line 137, in render_to_string
    raise TemplateDoesNotExist(template_name)
TemplateDoesNotExist: DynamfitExample.html
[27/Apr/2017 11:48:42] ERROR [django.request:256] Internal Server Error: /DynamfitExampleInput
Traceback (most recent call last):
  File "/home/NANOMINE/anaconda2/lib/python2.7/site-packages/django/core/handlers/base.py", line 132, in get_response
    response = wrapped_callback(request, *callback_args, **callback_kwargs)
  File "/home/NANOMINE/Develop/mdcs-v1.5_rc1/dynamfit/views.py", line 201, in sampleinput
    return redirect('/login')
  File "/home/NANOMINE/anaconda2/lib/python2.7/site-packages/django/shortcuts.py", line 45, in render_to_response
    using=using)
  File "/home/NANOMINE/anaconda2/lib/python2.7/site-packages/django/template/loader.py", line 137, in render_to_string
    raise TemplateDoesNotExist(template_name)
TemplateDoesNotExist: DynamfitExampleInput.html
[27/Apr/2017 11:49:59] ERROR [django.request:256] Internal Server Error: /DynamfitExampleRun
Traceback (most recent call last):
  File "/home/NANOMINE/anaconda2/lib/python2.7/site-packages/django/core/handlers/base.py", line 132, in get_response
    response = wrapped_callback(request, *callback_args, **callback_kwargs)
  File "/home/NANOMINE/Develop/mdcs-v1.5_rc1/dynamfit/views.py", line 215, in samplerun
    return redirect('/login')
  File "/home/NANOMINE/anaconda2/lib/python2.7/site-packages/django/shortcuts.py", line 45, in render_to_response
    using=using)
  File "/home/NANOMINE/anaconda2/lib/python2.7/site-packages/django/template/loader.py", line 137, in render_to_string
    raise TemplateDoesNotExist(template_name)
TemplateDoesNotExist: DynamfitExampleRun.html
[27/Apr/2017 13:56:26] ERROR [django.request:256] Internal Server Error: /dynamfit/
Traceback (most recent call last):
  File "/home/NANOMINE/anaconda2/lib/python2.7/site-packages/django/core/handlers/base.py", line 132, in get_response
    response = wrapped_callback(request, *callback_args, **callback_kwargs)
  File "/home/NANOMINE/Develop/mdcs-v1.5_rc1/dynamfit/views.py", line 33, in home
    # Handle file upload
IOError: [Errno 2] No such file or directory: './Dynamfit/RunCount.num'
[27/Apr/2017 13:57:17] DEBUG [paramiko.transport:282] starting thread (client mode): 0xa91c2610L
[27/Apr/2017 13:57:17] DEBUG [paramiko.transport:282] Local version/idstring: SSH-2.0-paramiko_2.1.2
[27/Apr/2017 13:57:17] DEBUG [paramiko.transport:282] Remote version/idstring: SSH-2.0-OpenSSH_6.6.1
[27/Apr/2017 13:57:17] INFO [paramiko.transport:282] Connected (version 2.0, client OpenSSH_6.6.1)
[27/Apr/2017 13:57:17] DEBUG [paramiko.transport:282] kex algos:[u'curve25519-sha256@libssh.org', u'ecdh-sha2-nistp256', u'ecdh-sha2-nistp384', u'ecdh-sha2-nistp521', u'diffie-hellman-group-exchange-sha256', u'diffie-hellman-group-exchange-sha1', u'diffie-hellman-group14-sha1', u'diffie-hellman-group1-sha1'] server key:[u'ssh-rsa', u'ecdsa-sha2-nistp256', u'ssh-ed25519'] client encrypt:[u'aes128-ctr', u'aes192-ctr', u'aes256-ctr', u'arcfour256', u'arcfour128', u'aes128-gcm@openssh.com', u'aes256-gcm@openssh.com', u'chacha20-poly1305@openssh.com', u'aes128-cbc', u'3des-cbc', u'blowfish-cbc', u'cast128-cbc', u'aes192-cbc', u'aes256-cbc', u'arcfour', u'rijndael-cbc@lysator.liu.se'] server encrypt:[u'aes128-ctr', u'aes192-ctr', u'aes256-ctr', u'arcfour256', u'arcfour128', u'aes128-gcm@openssh.com', u'aes256-gcm@openssh.com', u'chacha20-poly1305@openssh.com', u'aes128-cbc', u'3des-cbc', u'blowfish-cbc', u'cast128-cbc', u'aes192-cbc', u'aes256-cbc', u'arcfour', u'rijndael-cbc@lysator.liu.se'] client mac:[u'hmac-md5-etm@openssh.com', u'hmac-sha1-etm@openssh.com', u'umac-64-etm@openssh.com', u'umac-128-etm@openssh.com', u'hmac-sha2-256-etm@openssh.com', u'hmac-sha2-512-etm@openssh.com', u'hmac-ripemd160-etm@openssh.com', u'hmac-sha1-96-etm@openssh.com', u'hmac-md5-96-etm@openssh.com', u'hmac-md5', u'hmac-sha1', u'umac-64@openssh.com', u'umac-128@openssh.com', u'hmac-sha2-256', u'hmac-sha2-512', u'hmac-ripemd160', u'hmac-ripemd160@openssh.com', u'hmac-sha1-96', u'hmac-md5-96'] server mac:[u'hmac-md5-etm@openssh.com', u'hmac-sha1-etm@openssh.com', u'umac-64-etm@openssh.com', u'umac-128-etm@openssh.com', u'hmac-sha2-256-etm@openssh.com', u'hmac-sha2-512-etm@openssh.com', u'hmac-ripemd160-etm@openssh.com', u'hmac-sha1-96-etm@openssh.com', u'hmac-md5-96-etm@openssh.com', u'hmac-md5', u'hmac-sha1', u'umac-64@openssh.com', u'umac-128@openssh.com', u'hmac-sha2-256', u'hmac-sha2-512', u'hmac-ripemd160', u'hmac-ripemd160@openssh.com', u'hmac-sha1-96', u'hmac-md5-96'] client compress:[u'none', u'zlib@openssh.com'] server compress:[u'none', u'zlib@openssh.com'] client lang:[u''] server lang:[u''] kex follows?False
[27/Apr/2017 13:57:17] DEBUG [paramiko.transport:282] Kex agreed: diffie-hellman-group1-sha1
[27/Apr/2017 13:57:17] DEBUG [paramiko.transport:282] Cipher agreed: aes128-ctr
[27/Apr/2017 13:57:17] DEBUG [paramiko.transport:282] MAC agreed: hmac-sha2-256
[27/Apr/2017 13:57:17] DEBUG [paramiko.transport:282] Compression agreed: none
[27/Apr/2017 13:57:17] DEBUG [paramiko.transport:282] kex engine KexGroup1 specified hash_algo <built-in function openssl_sha1>
[27/Apr/2017 13:57:17] DEBUG [paramiko.transport:282] Switch to new keys ...
