[24/Jul/2016 18:40:18] ERROR [django.request:231] Internal Server Error: /DynamfitExample
Traceback (most recent call last):
  File "/home/NANOMINE/usr/local/lib/python2.7/site-packages/django/core/handlers/base.py", line 87, in get_response
    response = middleware_method(request)
  File "/home/NANOMINE/usr/local/lib/python2.7/site-packages/django/middleware/common.py", line 72, in process_request
    if (not urlresolvers.is_valid_path(request.path_info, urlconf) and
  File "/home/NANOMINE/usr/local/lib/python2.7/site-packages/django/core/urlresolvers.py", line 614, in is_valid_path
    resolve(path, urlconf)
  File "/home/NANOMINE/usr/local/lib/python2.7/site-packages/django/core/urlresolvers.py", line 489, in resolve
    return get_resolver(urlconf).resolve(path)
  File "/home/NANOMINE/usr/local/lib/python2.7/site-packages/django/core/urlresolvers.py", line 338, in resolve
    for pattern in self.url_patterns:
  File "/home/NANOMINE/usr/local/lib/python2.7/site-packages/django/core/urlresolvers.py", line 367, in url_patterns
    patterns = getattr(self.urlconf_module, "urlpatterns", self.urlconf_module)
  File "/home/NANOMINE/usr/local/lib/python2.7/site-packages/django/core/urlresolvers.py", line 361, in urlconf_module
    self._urlconf_module = import_module(self.urlconf_name)
  File "/home/NANOMINE/usr/local/lib/python2.7/importlib/__init__.py", line 37, in import_module
    __import__(name)
  File "/home/NANOMINE/Develop/mdcs/mgi/urls.py", line 50
    url(r'^RECONSample$', 'RECON.views.sample' name='RECON_sample'),
                                                  ^
SyntaxError: invalid syntax
[24/Jul/2016 18:47:59] WARNING [django.request:143] Not Found: /favicon.ico
[24/Jul/2016 19:34:54] ERROR [django.request:231] Internal Server Error: /RECONCheck
Traceback (most recent call last):
  File "/home/NANOMINE/usr/local/lib/python2.7/site-packages/django/core/handlers/base.py", line 111, in get_response
    response = wrapped_callback(request, *callback_args, **callback_kwargs)
  File "/home/NANOMINE/Develop/mdcs/RECON/views.py", line 166, in check
    'out1':out1, 'out2':out2, 'out3':out3, 'out5':out5, 'out6':out6, 'out7':out7,
UnboundLocalError: local variable 'out1' referenced before assignment
[24/Jul/2016 19:44:43] ERROR [django.request:231] Internal Server Error: /RECONCheck
Traceback (most recent call last):
  File "/home/NANOMINE/usr/local/lib/python2.7/site-packages/django/core/handlers/base.py", line 111, in get_response
    response = wrapped_callback(request, *callback_args, **callback_kwargs)
  File "/home/NANOMINE/Develop/mdcs/RECON/views.py", line 148, in check
    jobID = request.POST['jobID']
  File "/home/NANOMINE/usr/local/lib/python2.7/site-packages/django/utils/datastructures.py", line 319, in __getitem__
    raise MultiValueDictKeyError(repr(key))
MultiValueDictKeyError: "'jobID'"
[24/Jul/2016 19:44:51] ERROR [django.request:231] Internal Server Error: /RECONCheck
Traceback (most recent call last):
  File "/home/NANOMINE/usr/local/lib/python2.7/site-packages/django/core/handlers/base.py", line 111, in get_response
    response = wrapped_callback(request, *callback_args, **callback_kwargs)
  File "/home/NANOMINE/Develop/mdcs/RECON/views.py", line 148, in check
    jobID = request.POST['jobID']
  File "/home/NANOMINE/usr/local/lib/python2.7/site-packages/django/utils/datastructures.py", line 319, in __getitem__
    raise MultiValueDictKeyError(repr(key))
MultiValueDictKeyError: "'jobID'"
[24/Jul/2016 19:56:54] ERROR [django.request:231] Internal Server Error: /RECONCheck
Traceback (most recent call last):
  File "/home/NANOMINE/usr/local/lib/python2.7/site-packages/django/core/handlers/base.py", line 111, in get_response
    response = wrapped_callback(request, *callback_args, **callback_kwargs)
  File "/home/NANOMINE/Develop/mdcs/RECON/views.py", line 155, in check
    if os.path.exists(WORKDING_DIR+'/'+filename+'_3D_recon_3D_geometry.mat'): # the last file code generated, in 95 is this, in 149 should be plots
NameError: global name 'filename' is not defined
[24/Jul/2016 19:57:00] ERROR [django.request:231] Internal Server Error: /RECONCheck
Traceback (most recent call last):
  File "/home/NANOMINE/usr/local/lib/python2.7/site-packages/django/core/handlers/base.py", line 111, in get_response
    response = wrapped_callback(request, *callback_args, **callback_kwargs)
  File "/home/NANOMINE/Develop/mdcs/RECON/views.py", line 155, in check
    if os.path.exists(WORKDING_DIR+'/'+filename+'_3D_recon_3D_geometry.mat'): # the last file code generated, in 95 is this, in 149 should be plots
NameError: global name 'filename' is not defined
[24/Jul/2016 20:40:06] ERROR [django.request:231] Internal Server Error: /RECONCheck
Traceback (most recent call last):
  File "/home/NANOMINE/usr/local/lib/python2.7/site-packages/django/core/handlers/base.py", line 111, in get_response
    response = wrapped_callback(request, *callback_args, **callback_kwargs)
  File "/home/NANOMINE/Develop/mdcs/RECON/views.py", line 151, in check
    if os.path.exists(WORKDING_DIR+'/'+filename+'_3D_recon_3D_geometry.mat'): # the last file code generated, in 95 is this, in 149 should be plots
NameError: global name 'filename' is not defined
[24/Jul/2016 20:57:19] ERROR [django.request:231] Internal Server Error: /RECONCheck
Traceback (most recent call last):
  File "/home/NANOMINE/usr/local/lib/python2.7/site-packages/django/core/handlers/base.py", line 111, in get_response
    response = wrapped_callback(request, *callback_args, **callback_kwargs)
  File "/home/NANOMINE/Develop/mdcs/RECON/views.py", line 151, in check
    if os.path.exists(WORKDING_DIR+'/'+filename+'_results/'+filename+'_3D_recon_3D_geometry.mat'): # the last file code generated, in 95 is this, in 149 should be plots
NameError: global name 'filename' is not defined
[25/Jul/2016 02:20:34] WARNING [django.request:143] Not Found: /AUTOFITExample
[25/Jul/2016 02:20:48] WARNING [django.request:143] Not Found: /AUTOFITSample
[25/Jul/2016 03:00:46] WARNING [django.request:143] Not Found: /apple-touch-icon-precomposed.png
[25/Jul/2016 03:00:46] WARNING [django.request:143] Not Found: /apple-touch-icon.png
[25/Jul/2016 12:24:07] WARNING [django.request:143] Not Found: /apple-touch-icon-precomposed.png
[25/Jul/2016 12:24:07] WARNING [django.request:143] Not Found: /favicon.ico
[25/Jul/2016 12:24:08] WARNING [django.request:143] Not Found: /apple-touch-icon.png
[25/Jul/2016 13:31:20] WARNING [django.request:143] Not Found: /favicon.ico
[25/Jul/2016 13:39:59] WARNING [django.request:143] Not Found: /favicon.ico
[25/Jul/2016 14:07:52] WARNING [django.request:143] Not Found: /apple-touch-icon-precomposed.png
[25/Jul/2016 14:07:52] WARNING [django.request:143] Not Found: /favicon.ico
[25/Jul/2016 14:07:52] WARNING [django.request:143] Not Found: /apple-touch-icon.png
[25/Jul/2016 14:07:52] WARNING [django.request:143] Not Found: /apple-touch-icon-precomposed.png
[25/Jul/2016 14:07:52] WARNING [django.request:143] Not Found: /apple-touch-icon.png
[25/Jul/2016 14:33:31] ERROR [django.request:231] Internal Server Error: /login
Traceback (most recent call last):
  File "/home/NANOMINE/usr/local/lib/python2.7/site-packages/django/core/handlers/base.py", line 137, in get_response
    response = response.render()
  File "/home/NANOMINE/usr/local/lib/python2.7/site-packages/django/template/response.py", line 103, in render
    self.content = self.rendered_content
  File "/home/NANOMINE/usr/local/lib/python2.7/site-packages/django/template/response.py", line 80, in rendered_content
    content = template.render(context)
  File "/home/NANOMINE/usr/local/lib/python2.7/site-packages/django/template/base.py", line 148, in render
    return self._render(context)
  File "/home/NANOMINE/usr/local/lib/python2.7/site-packages/django/template/base.py", line 142, in _render
    return self.nodelist.render(context)
  File "/home/NANOMINE/usr/local/lib/python2.7/site-packages/django/template/base.py", line 844, in render
    bit = self.render_node(node, context)
  File "/home/NANOMINE/usr/local/lib/python2.7/site-packages/django/template/base.py", line 858, in render_node
    return node.render(context)
  File "/home/NANOMINE/usr/local/lib/python2.7/site-packages/django/template/loader_tags.py", line 126, in render
    return compiled_parent._render(context)
  File "/home/NANOMINE/usr/local/lib/python2.7/site-packages/django/template/base.py", line 142, in _render
    return self.nodelist.render(context)
  File "/home/NANOMINE/usr/local/lib/python2.7/site-packages/django/template/base.py", line 844, in render
    bit = self.render_node(node, context)
  File "/home/NANOMINE/usr/local/lib/python2.7/site-packages/django/template/base.py", line 858, in render_node
    return node.render(context)
  File "/home/NANOMINE/usr/local/lib/python2.7/site-packages/django/template/loader_tags.py", line 126, in render
    return compiled_parent._render(context)
  File "/home/NANOMINE/usr/local/lib/python2.7/site-packages/django/template/base.py", line 142, in _render
    return self.nodelist.render(context)
  File "/home/NANOMINE/usr/local/lib/python2.7/site-packages/django/template/base.py", line 844, in render
    bit = self.render_node(node, context)
  File "/home/NANOMINE/usr/local/lib/python2.7/site-packages/django/template/base.py", line 858, in render_node
    return node.render(context)
  File "/home/NANOMINE/usr/local/lib/python2.7/site-packages/django/template/loader_tags.py", line 65, in render
    result = block.nodelist.render(context)
  File "/home/NANOMINE/usr/local/lib/python2.7/site-packages/django/template/base.py", line 844, in render
    bit = self.render_node(node, context)
  File "/home/NANOMINE/usr/local/lib/python2.7/site-packages/django/template/base.py", line 858, in render_node
    return node.render(context)
  File "/home/NANOMINE/usr/local/lib/python2.7/site-packages/django/template/loader_tags.py", line 65, in render
    result = block.nodelist.render(context)
  File "/home/NANOMINE/usr/local/lib/python2.7/site-packages/django/template/base.py", line 844, in render
    bit = self.render_node(node, context)
  File "/home/NANOMINE/usr/local/lib/python2.7/site-packages/django/template/base.py", line 858, in render_node
    return node.render(context)
  File "/home/NANOMINE/usr/local/lib/python2.7/site-packages/django/template/defaulttags.py", line 444, in render
    url = reverse(view_name, args=args, kwargs=kwargs, current_app=context.current_app)
  File "/home/NANOMINE/usr/local/lib/python2.7/site-packages/django/core/urlresolvers.py", line 546, in reverse
    return iri_to_uri(resolver._reverse_with_prefix(view, prefix, *args, **kwargs))
  File "/home/NANOMINE/usr/local/lib/python2.7/site-packages/django/core/urlresolvers.py", line 410, in _reverse_with_prefix
    self._populate()
  File "/home/NANOMINE/usr/local/lib/python2.7/site-packages/django/core/urlresolvers.py", line 292, in _populate
    for name in pattern.reverse_dict:
  File "/home/NANOMINE/usr/local/lib/python2.7/site-packages/django/core/urlresolvers.py", line 315, in reverse_dict
    self._populate()
  File "/home/NANOMINE/usr/local/lib/python2.7/site-packages/django/core/urlresolvers.py", line 303, in _populate
    lookups.appendlist(pattern.callback, (bits, p_pattern, pattern.default_args))
  File "/home/NANOMINE/usr/local/lib/python2.7/site-packages/django/core/urlresolvers.py", line 231, in callback
    self._callback = get_callable(self._callback_str)
  File "/home/NANOMINE/usr/local/lib/python2.7/site-packages/django/utils/lru_cache.py", line 101, in wrapper
    result = user_function(*args, **kwds)
  File "/home/NANOMINE/usr/local/lib/python2.7/site-packages/django/core/urlresolvers.py", line 118, in get_callable
    (lookup_view, mod_name))
ViewDoesNotExist: Could not import Dynamfit.views.check. View does not exist in module Dynamfit.views.
[25/Jul/2016 14:33:48] ERROR [django.request:231] Internal Server Error: /login
Traceback (most recent call last):
  File "/home/NANOMINE/usr/local/lib/python2.7/site-packages/django/core/handlers/base.py", line 137, in get_response
    response = response.render()
  File "/home/NANOMINE/usr/local/lib/python2.7/site-packages/django/template/response.py", line 103, in render
    self.content = self.rendered_content
  File "/home/NANOMINE/usr/local/lib/python2.7/site-packages/django/template/response.py", line 80, in rendered_content
    content = template.render(context)
  File "/home/NANOMINE/usr/local/lib/python2.7/site-packages/django/template/base.py", line 148, in render
    return self._render(context)
  File "/home/NANOMINE/usr/local/lib/python2.7/site-packages/django/template/base.py", line 142, in _render
    return self.nodelist.render(context)
  File "/home/NANOMINE/usr/local/lib/python2.7/site-packages/django/template/base.py", line 844, in render
    bit = self.render_node(node, context)
  File "/home/NANOMINE/usr/local/lib/python2.7/site-packages/django/template/base.py", line 858, in render_node
    return node.render(context)
  File "/home/NANOMINE/usr/local/lib/python2.7/site-packages/django/template/loader_tags.py", line 126, in render
    return compiled_parent._render(context)
  File "/home/NANOMINE/usr/local/lib/python2.7/site-packages/django/template/base.py", line 142, in _render
    return self.nodelist.render(context)
  File "/home/NANOMINE/usr/local/lib/python2.7/site-packages/django/template/base.py", line 844, in render
    bit = self.render_node(node, context)
  File "/home/NANOMINE/usr/local/lib/python2.7/site-packages/django/template/base.py", line 858, in render_node
    return node.render(context)
  File "/home/NANOMINE/usr/local/lib/python2.7/site-packages/django/template/loader_tags.py", line 126, in render
    return compiled_parent._render(context)
  File "/home/NANOMINE/usr/local/lib/python2.7/site-packages/django/template/base.py", line 142, in _render
    return self.nodelist.render(context)
  File "/home/NANOMINE/usr/local/lib/python2.7/site-packages/django/template/base.py", line 844, in render
    bit = self.render_node(node, context)
  File "/home/NANOMINE/usr/local/lib/python2.7/site-packages/django/template/base.py", line 858, in render_node
    return node.render(context)
  File "/home/NANOMINE/usr/local/lib/python2.7/site-packages/django/template/loader_tags.py", line 65, in render
    result = block.nodelist.render(context)
  File "/home/NANOMINE/usr/local/lib/python2.7/site-packages/django/template/base.py", line 844, in render
    bit = self.render_node(node, context)
  File "/home/NANOMINE/usr/local/lib/python2.7/site-packages/django/template/base.py", line 858, in render_node
    return node.render(context)
  File "/home/NANOMINE/usr/local/lib/python2.7/site-packages/django/template/loader_tags.py", line 65, in render
    result = block.nodelist.render(context)
  File "/home/NANOMINE/usr/local/lib/python2.7/site-packages/django/template/base.py", line 844, in render
    bit = self.render_node(node, context)
  File "/home/NANOMINE/usr/local/lib/python2.7/site-packages/django/template/base.py", line 858, in render_node
    return node.render(context)
  File "/home/NANOMINE/usr/local/lib/python2.7/site-packages/django/template/defaulttags.py", line 444, in render
    url = reverse(view_name, args=args, kwargs=kwargs, current_app=context.current_app)
  File "/home/NANOMINE/usr/local/lib/python2.7/site-packages/django/core/urlresolvers.py", line 546, in reverse
    return iri_to_uri(resolver._reverse_with_prefix(view, prefix, *args, **kwargs))
  File "/home/NANOMINE/usr/local/lib/python2.7/site-packages/django/core/urlresolvers.py", line 410, in _reverse_with_prefix
    self._populate()
  File "/home/NANOMINE/usr/local/lib/python2.7/site-packages/django/core/urlresolvers.py", line 292, in _populate
    for name in pattern.reverse_dict:
  File "/home/NANOMINE/usr/local/lib/python2.7/site-packages/django/core/urlresolvers.py", line 315, in reverse_dict
    self._populate()
  File "/home/NANOMINE/usr/local/lib/python2.7/site-packages/django/core/urlresolvers.py", line 303, in _populate
    lookups.appendlist(pattern.callback, (bits, p_pattern, pattern.default_args))
  File "/home/NANOMINE/usr/local/lib/python2.7/site-packages/django/core/urlresolvers.py", line 231, in callback
    self._callback = get_callable(self._callback_str)
  File "/home/NANOMINE/usr/local/lib/python2.7/site-packages/django/utils/lru_cache.py", line 101, in wrapper
    result = user_function(*args, **kwds)
  File "/home/NANOMINE/usr/local/lib/python2.7/site-packages/django/core/urlresolvers.py", line 118, in get_callable
    (lookup_view, mod_name))
ViewDoesNotExist: Could not import Dynamfit.views.check. View does not exist in module Dynamfit.views.
[25/Jul/2016 14:34:34] ERROR [django.request:231] Internal Server Error: /AUTOFIT/
Traceback (most recent call last):
  File "/home/NANOMINE/usr/local/lib/python2.7/site-packages/django/core/handlers/base.py", line 98, in get_response
    resolver_match = resolver.resolve(request.path_info)
  File "/home/NANOMINE/usr/local/lib/python2.7/site-packages/django/core/urlresolvers.py", line 340, in resolve
    sub_match = pattern.resolve(new_path)
  File "/home/NANOMINE/usr/local/lib/python2.7/site-packages/django/core/urlresolvers.py", line 340, in resolve
    sub_match = pattern.resolve(new_path)
  File "/home/NANOMINE/usr/local/lib/python2.7/site-packages/django/core/urlresolvers.py", line 224, in resolve
    return ResolverMatch(self.callback, args, kwargs, self.name)
  File "/home/NANOMINE/usr/local/lib/python2.7/site-packages/django/core/urlresolvers.py", line 231, in callback
    self._callback = get_callable(self._callback_str)
  File "/home/NANOMINE/usr/local/lib/python2.7/site-packages/django/utils/lru_cache.py", line 101, in wrapper
    result = user_function(*args, **kwds)
  File "/home/NANOMINE/usr/local/lib/python2.7/site-packages/django/core/urlresolvers.py", line 97, in get_callable
    mod = import_module(mod_name)
  File "/home/NANOMINE/usr/local/lib/python2.7/importlib/__init__.py", line 37, in import_module
    __import__(name)
  File "/home/NANOMINE/Develop/mdcs/AUTOFIT/views.py", line 8, in <module>
    from AUTOFIT.models import Document
ImportError: cannot import name Document
[25/Jul/2016 14:34:34] WARNING [django.request:143] Not Found: /apple-touch-icon-precomposed.png
[25/Jul/2016 14:34:34] WARNING [django.request:143] Not Found: /favicon.ico
[25/Jul/2016 14:34:34] WARNING [django.request:143] Not Found: /apple-touch-icon.png
[25/Jul/2016 14:35:17] WARNING [django.request:143] Not Found: /mgi/
[25/Jul/2016 14:36:59] WARNING [django.request:143] Not Found: /mgi/
[25/Jul/2016 14:39:36] WARNING [django.request:143] Not Found: /mgi/
[25/Jul/2016 14:40:25] WARNING [django.request:143] Not Found: /mgi/
[25/Jul/2016 14:40:38] WARNING [django.request:143] Not Found: /mgi/
[25/Jul/2016 14:44:06] WARNING [django.request:143] Not Found: /mgi/
[25/Jul/2016 14:47:27] WARNING [django.request:143] Not Found: /mgi/
[25/Jul/2016 14:52:18] WARNING [django.request:143] Not Found: /mgi/
[25/Jul/2016 15:13:38] ERROR [django.request:231] Internal Server Error: /AUTOFIT/
Traceback (most recent call last):
  File "/home/NANOMINE/usr/local/lib/python2.7/site-packages/django/core/handlers/base.py", line 111, in get_response
    response = wrapped_callback(request, *callback_args, **callback_kwargs)
  File "/home/NANOMINE/Develop/mdcs/AUTOFIT/views.py", line 35, in home
    form = UploadFieldForm(request.POST, request.FILES)
NameError: global name 'UploadFieldForm' is not defined
[25/Jul/2016 15:14:50] ERROR [django.request:231] Internal Server Error: /AUTOFIT/
Traceback (most recent call last):
  File "/home/NANOMINE/usr/local/lib/python2.7/site-packages/django/core/handlers/base.py", line 111, in get_response
    response = wrapped_callback(request, *callback_args, **callback_kwargs)
  File "/home/NANOMINE/Develop/mdcs/AUTOFIT/views.py", line 35, in home
    form = UploadFieldForm(request.POST, request.FILES)
NameError: global name 'UploadFieldForm' is not defined
[25/Jul/2016 15:30:51] ERROR [django.request:231] Internal Server Error: /AUTOFIT/
Traceback (most recent call last):
  File "/home/NANOMINE/usr/local/lib/python2.7/site-packages/django/core/handlers/base.py", line 98, in get_response
    resolver_match = resolver.resolve(request.path_info)
  File "/home/NANOMINE/usr/local/lib/python2.7/site-packages/django/core/urlresolvers.py", line 340, in resolve
    sub_match = pattern.resolve(new_path)
  File "/home/NANOMINE/usr/local/lib/python2.7/site-packages/django/core/urlresolvers.py", line 224, in resolve
    return ResolverMatch(self.callback, args, kwargs, self.name)
  File "/home/NANOMINE/usr/local/lib/python2.7/site-packages/django/core/urlresolvers.py", line 231, in callback
    self._callback = get_callable(self._callback_str)
  File "/home/NANOMINE/usr/local/lib/python2.7/site-packages/django/utils/lru_cache.py", line 101, in wrapper
    result = user_function(*args, **kwds)
  File "/home/NANOMINE/usr/local/lib/python2.7/site-packages/django/core/urlresolvers.py", line 97, in get_callable
    mod = import_module(mod_name)
  File "/home/NANOMINE/usr/local/lib/python2.7/importlib/__init__.py", line 37, in import_module
    __import__(name)
  File "/home/NANOMINE/Develop/mdcs/AUTOFIT/views.py", line 10, in <module>
    from .forms import UploadFileForm
ImportError: cannot import name UploadFileForm
[25/Jul/2016 15:30:53] ERROR [django.request:231] Internal Server Error: /AUTOFIT/
Traceback (most recent call last):
  File "/home/NANOMINE/usr/local/lib/python2.7/site-packages/django/core/handlers/base.py", line 98, in get_response
    resolver_match = resolver.resolve(request.path_info)
  File "/home/NANOMINE/usr/local/lib/python2.7/site-packages/django/core/urlresolvers.py", line 340, in resolve
    sub_match = pattern.resolve(new_path)
  File "/home/NANOMINE/usr/local/lib/python2.7/site-packages/django/core/urlresolvers.py", line 224, in resolve
    return ResolverMatch(self.callback, args, kwargs, self.name)
  File "/home/NANOMINE/usr/local/lib/python2.7/site-packages/django/core/urlresolvers.py", line 231, in callback
    self._callback = get_callable(self._callback_str)
  File "/home/NANOMINE/usr/local/lib/python2.7/site-packages/django/utils/lru_cache.py", line 101, in wrapper
    result = user_function(*args, **kwds)
  File "/home/NANOMINE/usr/local/lib/python2.7/site-packages/django/core/urlresolvers.py", line 97, in get_callable
    mod = import_module(mod_name)
  File "/home/NANOMINE/usr/local/lib/python2.7/importlib/__init__.py", line 37, in import_module
    __import__(name)
  File "/home/NANOMINE/Develop/mdcs/AUTOFIT/views.py", line 10, in <module>
    from .forms import UploadFileForm
ImportError: cannot import name UploadFileForm
[25/Jul/2016 15:31:09] ERROR [django.request:231] Internal Server Error: /AUTOFIT/
Traceback (most recent call last):
  File "/home/NANOMINE/usr/local/lib/python2.7/site-packages/django/core/handlers/base.py", line 111, in get_response
    response = wrapped_callback(request, *callback_args, **callback_kwargs)
  File "/home/NANOMINE/Develop/mdcs/AUTOFIT/views.py", line 54, in home
    form = UploadFileForm()
NameError: global name 'UploadFileForm' is not defined
[25/Jul/2016 15:31:11] ERROR [django.request:231] Internal Server Error: /AUTOFIT/
Traceback (most recent call last):
  File "/home/NANOMINE/usr/local/lib/python2.7/site-packages/django/core/handlers/base.py", line 111, in get_response
    response = wrapped_callback(request, *callback_args, **callback_kwargs)
  File "/home/NANOMINE/Develop/mdcs/AUTOFIT/views.py", line 54, in home
    form = UploadFileForm()
NameError: global name 'UploadFileForm' is not defined
[25/Jul/2016 15:35:16] ERROR [django.request:231] Internal Server Error: /AUTOFIT/
Traceback (most recent call last):
  File "/home/NANOMINE/usr/local/lib/python2.7/site-packages/django/core/handlers/base.py", line 111, in get_response
    response = wrapped_callback(request, *callback_args, **callback_kwargs)
  File "/home/NANOMINE/Develop/mdcs/AUTOFIT/views.py", line 37, in home
    newdoc = Document(docfile = request.FILES.getlist['docfile'])
TypeError: 'instancemethod' object is not subscriptable
[25/Jul/2016 15:36:30] ERROR [django.request:231] Internal Server Error: /AUTOFIT/
Traceback (most recent call last):
  File "/home/NANOMINE/usr/local/lib/python2.7/site-packages/django/core/handlers/base.py", line 111, in get_response
    response = wrapped_callback(request, *callback_args, **callback_kwargs)
  File "/home/NANOMINE/Develop/mdcs/AUTOFIT/views.py", line 38, in home
    for f in newdoc:
TypeError: 'Document' object is not iterable
[25/Jul/2016 15:38:59] ERROR [django.request:231] Internal Server Error: /AUTOFIT/
Traceback (most recent call last):
  File "/home/NANOMINE/usr/local/lib/python2.7/site-packages/django/core/handlers/base.py", line 111, in get_response
    response = wrapped_callback(request, *callback_args, **callback_kwargs)
  File "/home/NANOMINE/Develop/mdcs/AUTOFIT/views.py", line 41, in home
    newdoc.save()
  File "/home/NANOMINE/usr/local/lib/python2.7/site-packages/django/db/models/base.py", line 590, in save
    force_update=force_update, update_fields=update_fields)
  File "/home/NANOMINE/usr/local/lib/python2.7/site-packages/django/db/models/base.py", line 618, in save_base
    updated = self._save_table(raw, cls, force_insert, force_update, using, update_fields)
  File "/home/NANOMINE/usr/local/lib/python2.7/site-packages/django/db/models/base.py", line 680, in _save_table
    forced_update)
  File "/home/NANOMINE/usr/local/lib/python2.7/site-packages/django/db/models/base.py", line 710, in _do_update
    filtered = base_qs.filter(pk=pk_val)
  File "/home/NANOMINE/usr/local/lib/python2.7/site-packages/django/db/models/query.py", line 691, in filter
    return self._filter_or_exclude(False, *args, **kwargs)
  File "/home/NANOMINE/usr/local/lib/python2.7/site-packages/django/db/models/query.py", line 709, in _filter_or_exclude
    clone.query.add_q(Q(*args, **kwargs))
  File "/home/NANOMINE/usr/local/lib/python2.7/site-packages/django/db/models/sql/query.py", line 1287, in add_q
    clause, require_inner = self._add_q(where_part, self.used_aliases)
  File "/home/NANOMINE/usr/local/lib/python2.7/site-packages/django/db/models/sql/query.py", line 1314, in _add_q
    current_negated=current_negated, connector=connector)
  File "/home/NANOMINE/usr/local/lib/python2.7/site-packages/django/db/models/sql/query.py", line 1186, in build_filter
    condition = self.build_lookup(lookups, col, value)
  File "/home/NANOMINE/usr/local/lib/python2.7/site-packages/django/db/models/sql/query.py", line 1094, in build_lookup
    return final_lookup(lhs, rhs)
  File "/home/NANOMINE/usr/local/lib/python2.7/site-packages/django/db/models/lookups.py", line 82, in __init__
    self.rhs = self.get_prep_lookup()
  File "/home/NANOMINE/usr/local/lib/python2.7/site-packages/django/db/models/lookups.py", line 85, in get_prep_lookup
    return self.lhs.output_field.get_prep_lookup(self.lookup_name, self.rhs)
  File "/home/NANOMINE/usr/local/lib/python2.7/site-packages/django/db/models/fields/__init__.py", line 646, in get_prep_lookup
    return self.get_prep_value(value)
  File "/home/NANOMINE/usr/local/lib/python2.7/site-packages/django/db/models/fields/__init__.py", line 915, in get_prep_value
    return int(value)
TypeError: int() argument must be a string or a number, not 'InMemoryUploadedFile'
[25/Jul/2016 15:43:42] ERROR [django.request:231] Internal Server Error: /dynamfit/
Traceback (most recent call last):
  File "/home/NANOMINE/usr/local/lib/python2.7/site-packages/django/core/handlers/base.py", line 111, in get_response
    response = wrapped_callback(request, *callback_args, **callback_kwargs)
  File "/home/NANOMINE/Develop/mdcs/Dynamfit/views.py", line 101, in home
    newdoc.save()
  File "/home/NANOMINE/usr/local/lib/python2.7/site-packages/django/db/models/base.py", line 590, in save
    force_update=force_update, update_fields=update_fields)
  File "/home/NANOMINE/usr/local/lib/python2.7/site-packages/django/db/models/base.py", line 618, in save_base
    updated = self._save_table(raw, cls, force_insert, force_update, using, update_fields)
  File "/home/NANOMINE/usr/local/lib/python2.7/site-packages/django/db/models/base.py", line 680, in _save_table
    forced_update)
  File "/home/NANOMINE/usr/local/lib/python2.7/site-packages/django/db/models/base.py", line 710, in _do_update
    filtered = base_qs.filter(pk=pk_val)
  File "/home/NANOMINE/usr/local/lib/python2.7/site-packages/django/db/models/query.py", line 691, in filter
    return self._filter_or_exclude(False, *args, **kwargs)
  File "/home/NANOMINE/usr/local/lib/python2.7/site-packages/django/db/models/query.py", line 709, in _filter_or_exclude
    clone.query.add_q(Q(*args, **kwargs))
  File "/home/NANOMINE/usr/local/lib/python2.7/site-packages/django/db/models/sql/query.py", line 1287, in add_q
    clause, require_inner = self._add_q(where_part, self.used_aliases)
  File "/home/NANOMINE/usr/local/lib/python2.7/site-packages/django/db/models/sql/query.py", line 1314, in _add_q
    current_negated=current_negated, connector=connector)
  File "/home/NANOMINE/usr/local/lib/python2.7/site-packages/django/db/models/sql/query.py", line 1186, in build_filter
    condition = self.build_lookup(lookups, col, value)
  File "/home/NANOMINE/usr/local/lib/python2.7/site-packages/django/db/models/sql/query.py", line 1094, in build_lookup
    return final_lookup(lhs, rhs)
  File "/home/NANOMINE/usr/local/lib/python2.7/site-packages/django/db/models/lookups.py", line 82, in __init__
    self.rhs = self.get_prep_lookup()
  File "/home/NANOMINE/usr/local/lib/python2.7/site-packages/django/db/models/lookups.py", line 85, in get_prep_lookup
    return self.lhs.output_field.get_prep_lookup(self.lookup_name, self.rhs)
  File "/home/NANOMINE/usr/local/lib/python2.7/site-packages/django/db/models/fields/__init__.py", line 646, in get_prep_lookup
    return self.get_prep_value(value)
  File "/home/NANOMINE/usr/local/lib/python2.7/site-packages/django/db/models/fields/__init__.py", line 915, in get_prep_value
    return int(value)
TypeError: int() argument must be a string or a number, not 'InMemoryUploadedFile'
[25/Jul/2016 15:53:17] WARNING [django.request:143] Not Found: /favicon.ico
[25/Jul/2016 15:55:12] ERROR [django.request:231] Internal Server Error: /AUTOFIT/
Traceback (most recent call last):
  File "/home/NANOMINE/usr/local/lib/python2.7/site-packages/django/core/handlers/base.py", line 98, in get_response
    resolver_match = resolver.resolve(request.path_info)
  File "/home/NANOMINE/usr/local/lib/python2.7/site-packages/django/core/urlresolvers.py", line 340, in resolve
    sub_match = pattern.resolve(new_path)
  File "/home/NANOMINE/usr/local/lib/python2.7/site-packages/django/core/urlresolvers.py", line 224, in resolve
    return ResolverMatch(self.callback, args, kwargs, self.name)
  File "/home/NANOMINE/usr/local/lib/python2.7/site-packages/django/core/urlresolvers.py", line 231, in callback
    self._callback = get_callable(self._callback_str)
  File "/home/NANOMINE/usr/local/lib/python2.7/site-packages/django/utils/lru_cache.py", line 101, in wrapper
    result = user_function(*args, **kwds)
  File "/home/NANOMINE/usr/local/lib/python2.7/site-packages/django/core/urlresolvers.py", line 97, in get_callable
    mod = import_module(mod_name)
  File "/home/NANOMINE/usr/local/lib/python2.7/importlib/__init__.py", line 37, in import_module
    __import__(name)
  File "/home/NANOMINE/Develop/mdcs/AUTOFIT/views.py", line 5, in <module>
    from .forms import *
  File "/home/NANOMINE/Develop/mdcs/AUTOFIT/forms.py", line 4, in <module>
    class DocumentForm(forms.Form):
  File "/home/NANOMINE/Develop/mdcs/AUTOFIT/forms.py", line 9, in DocumentForm
    min_num = 3
  File "/home/NANOMINE/usr/local/lib/python2.7/site-packages/django/forms/fields.py", line 577, in __init__
    super(FileField, self).__init__(*args, **kwargs)
TypeError: __init__() got an unexpected keyword argument 'min_num'
[25/Jul/2016 16:00:55] ERROR [django.request:231] Internal Server Error: /AUTOFIT/
Traceback (most recent call last):
  File "/home/NANOMINE/usr/local/lib/python2.7/site-packages/django/core/handlers/base.py", line 111, in get_response
    response = wrapped_callback(request, *callback_args, **callback_kwargs)
  File "/home/NANOMINE/Develop/mdcs/AUTOFIT/views.py", line 39, in home
    for f in docfile:
NameError: global name 'docfile' is not defined
[25/Jul/2016 22:16:07] WARNING [django.request:143] Not Found: /favicon.ico
[26/Jul/2016 04:39:56] ERROR [django.request:231] Internal Server Error: /login
Traceback (most recent call last):
  File "/home/NANOMINE/usr/local/lib/python2.7/site-packages/django/core/handlers/base.py", line 137, in get_response
    response = response.render()
  File "/home/NANOMINE/usr/local/lib/python2.7/site-packages/django/template/response.py", line 103, in render
    self.content = self.rendered_content
  File "/home/NANOMINE/usr/local/lib/python2.7/site-packages/django/template/response.py", line 80, in rendered_content
    content = template.render(context)
  File "/home/NANOMINE/usr/local/lib/python2.7/site-packages/django/template/base.py", line 148, in render
    return self._render(context)
  File "/home/NANOMINE/usr/local/lib/python2.7/site-packages/django/template/base.py", line 142, in _render
    return self.nodelist.render(context)
  File "/home/NANOMINE/usr/local/lib/python2.7/site-packages/django/template/base.py", line 844, in render
    bit = self.render_node(node, context)
  File "/home/NANOMINE/usr/local/lib/python2.7/site-packages/django/template/base.py", line 858, in render_node
    return node.render(context)
  File "/home/NANOMINE/usr/local/lib/python2.7/site-packages/django/template/loader_tags.py", line 126, in render
    return compiled_parent._render(context)
  File "/home/NANOMINE/usr/local/lib/python2.7/site-packages/django/template/base.py", line 142, in _render
    return self.nodelist.render(context)
  File "/home/NANOMINE/usr/local/lib/python2.7/site-packages/django/template/base.py", line 844, in render
    bit = self.render_node(node, context)
  File "/home/NANOMINE/usr/local/lib/python2.7/site-packages/django/template/base.py", line 858, in render_node
    return node.render(context)
  File "/home/NANOMINE/usr/local/lib/python2.7/site-packages/django/template/loader_tags.py", line 126, in render
    return compiled_parent._render(context)
  File "/home/NANOMINE/usr/local/lib/python2.7/site-packages/django/template/base.py", line 142, in _render
    return self.nodelist.render(context)
  File "/home/NANOMINE/usr/local/lib/python2.7/site-packages/django/template/base.py", line 844, in render
    bit = self.render_node(node, context)
  File "/home/NANOMINE/usr/local/lib/python2.7/site-packages/django/template/base.py", line 858, in render_node
    return node.render(context)
  File "/home/NANOMINE/usr/local/lib/python2.7/site-packages/django/template/loader_tags.py", line 65, in render
    result = block.nodelist.render(context)
  File "/home/NANOMINE/usr/local/lib/python2.7/site-packages/django/template/base.py", line 844, in render
    bit = self.render_node(node, context)
  File "/home/NANOMINE/usr/local/lib/python2.7/site-packages/django/template/base.py", line 858, in render_node
    return node.render(context)
  File "/home/NANOMINE/usr/local/lib/python2.7/site-packages/django/template/loader_tags.py", line 65, in render
    result = block.nodelist.render(context)
  File "/home/NANOMINE/usr/local/lib/python2.7/site-packages/django/template/base.py", line 844, in render
    bit = self.render_node(node, context)
  File "/home/NANOMINE/usr/local/lib/python2.7/site-packages/django/template/base.py", line 858, in render_node
    return node.render(context)
  File "/home/NANOMINE/usr/local/lib/python2.7/site-packages/django/template/defaulttags.py", line 444, in render
    url = reverse(view_name, args=args, kwargs=kwargs, current_app=context.current_app)
  File "/home/NANOMINE/usr/local/lib/python2.7/site-packages/django/core/urlresolvers.py", line 546, in reverse
    return iri_to_uri(resolver._reverse_with_prefix(view, prefix, *args, **kwargs))
  File "/home/NANOMINE/usr/local/lib/python2.7/site-packages/django/core/urlresolvers.py", line 410, in _reverse_with_prefix
    self._populate()
  File "/home/NANOMINE/usr/local/lib/python2.7/site-packages/django/core/urlresolvers.py", line 303, in _populate
    lookups.appendlist(pattern.callback, (bits, p_pattern, pattern.default_args))
  File "/home/NANOMINE/usr/local/lib/python2.7/site-packages/django/core/urlresolvers.py", line 231, in callback
    self._callback = get_callable(self._callback_str)
  File "/home/NANOMINE/usr/local/lib/python2.7/site-packages/django/utils/lru_cache.py", line 101, in wrapper
    result = user_function(*args, **kwds)
  File "/home/NANOMINE/usr/local/lib/python2.7/site-packages/django/core/urlresolvers.py", line 97, in get_callable
    mod = import_module(mod_name)
  File "/home/NANOMINE/usr/local/lib/python2.7/importlib/__init__.py", line 37, in import_module
    __import__(name)
  File "/home/NANOMINE/Develop/mdcs/AUTOFIT/views.py", line 198
    else:
        ^
IndentationError: unindent does not match any outer indentation level
[26/Jul/2016 04:40:01] ERROR [django.request:231] Internal Server Error: /curate/
Traceback (most recent call last):
  File "/home/NANOMINE/usr/local/lib/python2.7/site-packages/django/core/handlers/base.py", line 111, in get_response
    response = wrapped_callback(request, *callback_args, **callback_kwargs)
  File "/home/NANOMINE/Develop/mdcs/curate/views.py", line 71, in index
    return redirect('/login')
  File "/home/NANOMINE/usr/local/lib/python2.7/site-packages/django/shortcuts.py", line 74, in redirect
    return redirect_class(resolve_url(to, *args, **kwargs))
  File "/home/NANOMINE/usr/local/lib/python2.7/site-packages/django/shortcuts.py", line 158, in resolve_url
    return urlresolvers.reverse(to, args=args, kwargs=kwargs)
  File "/home/NANOMINE/usr/local/lib/python2.7/site-packages/django/core/urlresolvers.py", line 546, in reverse
    return iri_to_uri(resolver._reverse_with_prefix(view, prefix, *args, **kwargs))
  File "/home/NANOMINE/usr/local/lib/python2.7/site-packages/django/core/urlresolvers.py", line 410, in _reverse_with_prefix
    self._populate()
  File "/home/NANOMINE/usr/local/lib/python2.7/site-packages/django/core/urlresolvers.py", line 303, in _populate
    lookups.appendlist(pattern.callback, (bits, p_pattern, pattern.default_args))
  File "/home/NANOMINE/usr/local/lib/python2.7/site-packages/django/core/urlresolvers.py", line 231, in callback
    self._callback = get_callable(self._callback_str)
  File "/home/NANOMINE/usr/local/lib/python2.7/site-packages/django/utils/lru_cache.py", line 101, in wrapper
    result = user_function(*args, **kwds)
  File "/home/NANOMINE/usr/local/lib/python2.7/site-packages/django/core/urlresolvers.py", line 97, in get_callable
    mod = import_module(mod_name)
  File "/home/NANOMINE/usr/local/lib/python2.7/importlib/__init__.py", line 37, in import_module
    __import__(name)
  File "/home/NANOMINE/Develop/mdcs/AUTOFIT/views.py", line 198
    else:
        ^
IndentationError: unindent does not match any outer indentation level
[26/Jul/2016 04:40:19] ERROR [django.request:231] Internal Server Error: /curate/
Traceback (most recent call last):
  File "/home/NANOMINE/usr/local/lib/python2.7/site-packages/django/core/handlers/base.py", line 111, in get_response
    response = wrapped_callback(request, *callback_args, **callback_kwargs)
  File "/home/NANOMINE/Develop/mdcs/curate/views.py", line 71, in index
    return redirect('/login')
  File "/home/NANOMINE/usr/local/lib/python2.7/site-packages/django/shortcuts.py", line 74, in redirect
    return redirect_class(resolve_url(to, *args, **kwargs))
  File "/home/NANOMINE/usr/local/lib/python2.7/site-packages/django/shortcuts.py", line 158, in resolve_url
    return urlresolvers.reverse(to, args=args, kwargs=kwargs)
  File "/home/NANOMINE/usr/local/lib/python2.7/site-packages/django/core/urlresolvers.py", line 546, in reverse
    return iri_to_uri(resolver._reverse_with_prefix(view, prefix, *args, **kwargs))
  File "/home/NANOMINE/usr/local/lib/python2.7/site-packages/django/core/urlresolvers.py", line 410, in _reverse_with_prefix
    self._populate()
  File "/home/NANOMINE/usr/local/lib/python2.7/site-packages/django/core/urlresolvers.py", line 303, in _populate
    lookups.appendlist(pattern.callback, (bits, p_pattern, pattern.default_args))
  File "/home/NANOMINE/usr/local/lib/python2.7/site-packages/django/core/urlresolvers.py", line 231, in callback
    self._callback = get_callable(self._callback_str)
  File "/home/NANOMINE/usr/local/lib/python2.7/site-packages/django/utils/lru_cache.py", line 101, in wrapper
    result = user_function(*args, **kwds)
  File "/home/NANOMINE/usr/local/lib/python2.7/site-packages/django/core/urlresolvers.py", line 97, in get_callable
    mod = import_module(mod_name)
  File "/home/NANOMINE/usr/local/lib/python2.7/importlib/__init__.py", line 37, in import_module
    __import__(name)
  File "/home/NANOMINE/Develop/mdcs/AUTOFIT/views.py", line 198
    else:
        ^
IndentationError: unindent does not match any outer indentation level
[26/Jul/2016 04:43:48] ERROR [django.request:231] Internal Server Error: /curate/
Traceback (most recent call last):
  File "/home/NANOMINE/usr/local/lib/python2.7/site-packages/django/core/handlers/base.py", line 111, in get_response
    response = wrapped_callback(request, *callback_args, **callback_kwargs)
  File "/home/NANOMINE/Develop/mdcs/curate/views.py", line 71, in index
    return redirect('/login')
  File "/home/NANOMINE/usr/local/lib/python2.7/site-packages/django/shortcuts.py", line 74, in redirect
    return redirect_class(resolve_url(to, *args, **kwargs))
  File "/home/NANOMINE/usr/local/lib/python2.7/site-packages/django/shortcuts.py", line 158, in resolve_url
    return urlresolvers.reverse(to, args=args, kwargs=kwargs)
  File "/home/NANOMINE/usr/local/lib/python2.7/site-packages/django/core/urlresolvers.py", line 546, in reverse
    return iri_to_uri(resolver._reverse_with_prefix(view, prefix, *args, **kwargs))
  File "/home/NANOMINE/usr/local/lib/python2.7/site-packages/django/core/urlresolvers.py", line 410, in _reverse_with_prefix
    self._populate()
  File "/home/NANOMINE/usr/local/lib/python2.7/site-packages/django/core/urlresolvers.py", line 303, in _populate
    lookups.appendlist(pattern.callback, (bits, p_pattern, pattern.default_args))
  File "/home/NANOMINE/usr/local/lib/python2.7/site-packages/django/core/urlresolvers.py", line 231, in callback
    self._callback = get_callable(self._callback_str)
  File "/home/NANOMINE/usr/local/lib/python2.7/site-packages/django/utils/lru_cache.py", line 101, in wrapper
    result = user_function(*args, **kwds)
  File "/home/NANOMINE/usr/local/lib/python2.7/site-packages/django/core/urlresolvers.py", line 97, in get_callable
    mod = import_module(mod_name)
  File "/home/NANOMINE/usr/local/lib/python2.7/importlib/__init__.py", line 37, in import_module
    __import__(name)
  File "/home/NANOMINE/Develop/mdcs/AUTOFIT/views.py", line 198
    else:
        ^
IndentationError: unindent does not match any outer indentation level
[26/Jul/2016 04:43:52] ERROR [django.request:231] Internal Server Error: /curate/
Traceback (most recent call last):
  File "/home/NANOMINE/usr/local/lib/python2.7/site-packages/django/core/handlers/base.py", line 111, in get_response
    response = wrapped_callback(request, *callback_args, **callback_kwargs)
  File "/home/NANOMINE/Develop/mdcs/curate/views.py", line 71, in index
    return redirect('/login')
  File "/home/NANOMINE/usr/local/lib/python2.7/site-packages/django/shortcuts.py", line 74, in redirect
    return redirect_class(resolve_url(to, *args, **kwargs))
  File "/home/NANOMINE/usr/local/lib/python2.7/site-packages/django/shortcuts.py", line 158, in resolve_url
    return urlresolvers.reverse(to, args=args, kwargs=kwargs)
  File "/home/NANOMINE/usr/local/lib/python2.7/site-packages/django/core/urlresolvers.py", line 546, in reverse
    return iri_to_uri(resolver._reverse_with_prefix(view, prefix, *args, **kwargs))
  File "/home/NANOMINE/usr/local/lib/python2.7/site-packages/django/core/urlresolvers.py", line 410, in _reverse_with_prefix
    self._populate()
  File "/home/NANOMINE/usr/local/lib/python2.7/site-packages/django/core/urlresolvers.py", line 303, in _populate
    lookups.appendlist(pattern.callback, (bits, p_pattern, pattern.default_args))
  File "/home/NANOMINE/usr/local/lib/python2.7/site-packages/django/core/urlresolvers.py", line 231, in callback
    self._callback = get_callable(self._callback_str)
  File "/home/NANOMINE/usr/local/lib/python2.7/site-packages/django/utils/lru_cache.py", line 101, in wrapper
    result = user_function(*args, **kwds)
  File "/home/NANOMINE/usr/local/lib/python2.7/site-packages/django/core/urlresolvers.py", line 97, in get_callable
    mod = import_module(mod_name)
  File "/home/NANOMINE/usr/local/lib/python2.7/importlib/__init__.py", line 37, in import_module
    __import__(name)
  File "/home/NANOMINE/Develop/mdcs/AUTOFIT/views.py", line 198
    else:
        ^
IndentationError: unindent does not match any outer indentation level
[26/Jul/2016 04:47:07] ERROR [django.request:231] Internal Server Error: /curate/
Traceback (most recent call last):
  File "/home/NANOMINE/usr/local/lib/python2.7/site-packages/django/core/handlers/base.py", line 111, in get_response
    response = wrapped_callback(request, *callback_args, **callback_kwargs)
  File "/home/NANOMINE/Develop/mdcs/curate/views.py", line 71, in index
    return redirect('/login')
  File "/home/NANOMINE/usr/local/lib/python2.7/site-packages/django/shortcuts.py", line 74, in redirect
    return redirect_class(resolve_url(to, *args, **kwargs))
  File "/home/NANOMINE/usr/local/lib/python2.7/site-packages/django/shortcuts.py", line 158, in resolve_url
    return urlresolvers.reverse(to, args=args, kwargs=kwargs)
  File "/home/NANOMINE/usr/local/lib/python2.7/site-packages/django/core/urlresolvers.py", line 546, in reverse
    return iri_to_uri(resolver._reverse_with_prefix(view, prefix, *args, **kwargs))
  File "/home/NANOMINE/usr/local/lib/python2.7/site-packages/django/core/urlresolvers.py", line 410, in _reverse_with_prefix
    self._populate()
  File "/home/NANOMINE/usr/local/lib/python2.7/site-packages/django/core/urlresolvers.py", line 303, in _populate
    lookups.appendlist(pattern.callback, (bits, p_pattern, pattern.default_args))
  File "/home/NANOMINE/usr/local/lib/python2.7/site-packages/django/core/urlresolvers.py", line 231, in callback
    self._callback = get_callable(self._callback_str)
  File "/home/NANOMINE/usr/local/lib/python2.7/site-packages/django/utils/lru_cache.py", line 101, in wrapper
    result = user_function(*args, **kwds)
  File "/home/NANOMINE/usr/local/lib/python2.7/site-packages/django/core/urlresolvers.py", line 97, in get_callable
    mod = import_module(mod_name)
  File "/home/NANOMINE/usr/local/lib/python2.7/importlib/__init__.py", line 37, in import_module
    __import__(name)
  File "/home/NANOMINE/Develop/mdcs/AUTOFIT/views.py", line 198
    else:
        ^
IndentationError: unindent does not match any outer indentation level
[26/Jul/2016 07:46:29] WARNING [django.request:143] Not Found: /robots.txt
[26/Jul/2016 13:41:27] ERROR [django.request:231] Internal Server Error: /logout
Traceback (most recent call last):
  File "/home/NANOMINE/usr/local/lib/python2.7/site-packages/django/core/handlers/base.py", line 111, in get_response
    response = wrapped_callback(request, *callback_args, **callback_kwargs)
  File "/home/NANOMINE/Develop/mdcs/mgi/views.py", line 125, in logout_view
    return redirect('/login')
  File "/home/NANOMINE/usr/local/lib/python2.7/site-packages/django/shortcuts.py", line 74, in redirect
    return redirect_class(resolve_url(to, *args, **kwargs))
  File "/home/NANOMINE/usr/local/lib/python2.7/site-packages/django/shortcuts.py", line 158, in resolve_url
    return urlresolvers.reverse(to, args=args, kwargs=kwargs)
  File "/home/NANOMINE/usr/local/lib/python2.7/site-packages/django/core/urlresolvers.py", line 546, in reverse
    return iri_to_uri(resolver._reverse_with_prefix(view, prefix, *args, **kwargs))
  File "/home/NANOMINE/usr/local/lib/python2.7/site-packages/django/core/urlresolvers.py", line 410, in _reverse_with_prefix
    self._populate()
  File "/home/NANOMINE/usr/local/lib/python2.7/site-packages/django/core/urlresolvers.py", line 303, in _populate
    lookups.appendlist(pattern.callback, (bits, p_pattern, pattern.default_args))
  File "/home/NANOMINE/usr/local/lib/python2.7/site-packages/django/core/urlresolvers.py", line 231, in callback
    self._callback = get_callable(self._callback_str)
  File "/home/NANOMINE/usr/local/lib/python2.7/site-packages/django/utils/lru_cache.py", line 101, in wrapper
    result = user_function(*args, **kwds)
  File "/home/NANOMINE/usr/local/lib/python2.7/site-packages/django/core/urlresolvers.py", line 97, in get_callable
    mod = import_module(mod_name)
  File "/home/NANOMINE/usr/local/lib/python2.7/importlib/__init__.py", line 37, in import_module
    __import__(name)
  File "/home/NANOMINE/Develop/mdcs/AUTOFIT/views.py", line 198
    else:
        ^
IndentationError: unindent does not match any outer indentation level
