[20/Aug/2016 21:04:18] ERROR [django.request:231] Internal Server Error: /XMLCONV/
Traceback (most recent call last):
  File "/home/NANOMINE/usr/local/lib/python2.7/site-packages/django/core/handlers/base.py", line 111, in get_response
    response = wrapped_callback(request, *callback_args, **callback_kwargs)
  File "/home/NANOMINE/Develop/mdcs/XMLCONV/views.py", line 33, in home
    newdoc.save()
  File "/home/NANOMINE/usr/local/lib/python2.7/site-packages/django/db/models/base.py", line 590, in save
    force_update=force_update, update_fields=update_fields)
  File "/home/NANOMINE/usr/local/lib/python2.7/site-packages/django/db/models/base.py", line 618, in save_base
    updated = self._save_table(raw, cls, force_insert, force_update, using, update_fields)
  File "/home/NANOMINE/usr/local/lib/python2.7/site-packages/django/db/models/base.py", line 699, in _save_table
    result = self._do_insert(cls._base_manager, using, fields, update_pk, raw)
  File "/home/NANOMINE/usr/local/lib/python2.7/site-packages/django/db/models/base.py", line 732, in _do_insert
    using=using, raw=raw)
  File "/home/NANOMINE/usr/local/lib/python2.7/site-packages/django/db/models/manager.py", line 92, in manager_method
    return getattr(self.get_queryset(), name)(*args, **kwargs)
  File "/home/NANOMINE/usr/local/lib/python2.7/site-packages/django/db/models/query.py", line 921, in _insert
    return query.get_compiler(using=using).execute_sql(return_id)
  File "/home/NANOMINE/usr/local/lib/python2.7/site-packages/django/db/models/sql/compiler.py", line 920, in execute_sql
    cursor.execute(sql, params)
  File "/home/NANOMINE/usr/local/lib/python2.7/site-packages/django/db/backends/utils.py", line 81, in execute
    return super(CursorDebugWrapper, self).execute(sql, params)
  File "/home/NANOMINE/usr/local/lib/python2.7/site-packages/django/db/backends/utils.py", line 65, in execute
    return self.cursor.execute(sql, params)
  File "/home/NANOMINE/usr/local/lib/python2.7/site-packages/django/db/utils.py", line 94, in __exit__
    six.reraise(dj_exc_type, dj_exc_value, traceback)
  File "/home/NANOMINE/usr/local/lib/python2.7/site-packages/django/db/backends/utils.py", line 65, in execute
    return self.cursor.execute(sql, params)
  File "/home/NANOMINE/usr/local/lib/python2.7/site-packages/django/db/backends/sqlite3/base.py", line 485, in execute
    return Database.Cursor.execute(self, query, params)
OperationalError: no such table: XMLCONV_document
[21/Aug/2016 14:52:44] WARNING [django.request:143] Not Found: /http://www.baidu.com/cache/global/img/gs.gif
[21/Aug/2016 19:53:25] WARNING [django.request:143] Not Found: /http://www.baidu.com/cache/global/img/gs.gif
[22/Aug/2016 00:18:39] WARNING [django.request:143] Not Found: /favicon.ico
[22/Aug/2016 13:38:16] WARNING [django.request:143] Not Found: /favicon.ico
[22/Aug/2016 23:17:31] WARNING [django.request:143] Not Found: /favicon.ico
[22/Aug/2016 23:52:27] ERROR [django.request:231] Internal Server Error: /rest/explore/select/all
Traceback (most recent call last):
  File "/home/NANOMINE/usr/local/lib/python2.7/site-packages/django/core/handlers/base.py", line 111, in get_response
    response = wrapped_callback(request, *callback_args, **callback_kwargs)
  File "/home/NANOMINE/usr/local/lib/python2.7/site-packages/django/views/generic/base.py", line 69, in view
    return self.dispatch(request, *args, **kwargs)
  File "/home/NANOMINE/usr/local/lib/python2.7/site-packages/django/views/decorators/csrf.py", line 57, in wrapped_view
    return view_func(*args, **kwargs)
  File "/home/NANOMINE/usr/local/lib/python2.7/site-packages/rest_framework/views.py", line 400, in dispatch
    response = self.handle_exception(exc)
  File "/home/NANOMINE/usr/local/lib/python2.7/site-packages/rest_framework/views.py", line 397, in dispatch
    response = handler(request, *args, **kwargs)
  File "/home/NANOMINE/usr/local/lib/python2.7/site-packages/rest_framework/decorators.py", line 49, in handler
    return func(*args, **kwargs)
  File "/home/NANOMINE/Develop/mdcs/api/views.py", line 255, in explore
    jsonDoc['content'] = xmltodict.unparse(jsonDoc['content'])
KeyError: 'content'
[23/Aug/2016 00:25:30] WARNING [django.request:143] Not Found: /http://www.baidu.com/cache/global/img/gs.gif
[23/Aug/2016 02:16:41] WARNING [django.request:143] Not Found: /favicon.ico
[23/Aug/2016 07:06:22] WARNING [django.request:143] Not Found: /http://www.baidu.com/cache/global/img/gs.gif
[24/Aug/2016 04:58:16] WARNING [django.request:143] Not Found: /http://www.baidu.com/cache/global/img/gs.gif
[24/Aug/2016 06:48:51] WARNING [django.request:143] Not Found: /robots.txt
[25/Aug/2016 03:55:52] WARNING [django.request:143] Not Found: /favicon.ico
[25/Aug/2016 03:55:52] WARNING [django.request:143] Not Found: /apple-touch-icon-precomposed.png
[25/Aug/2016 03:55:53] WARNING [django.request:143] Not Found: /apple-touch-icon.png
[25/Aug/2016 13:52:56] WARNING [django.request:143] Not Found: /XMLCONV
[27/Aug/2016 04:31:07] WARNING [django.request:143] Not Found: /favicon.ico
[02/Sep/2016 12:58:14] WARNING [django.request:143] Not Found: /robots.txt
[02/Sep/2016 17:19:24] WARNING [django.request:143] Not Found: /http://www.baidu.com/cache/global/img/gs.gif
[03/Sep/2016 21:53:50] WARNING [django.request:143] Not Found: /http://www.baidu.com/cache/global/img/gs.gif
[06/Sep/2016 13:34:46] WARNING [django.request:143] Not Found: /apple-touch-icon-precomposed.png
[06/Sep/2016 13:34:46] WARNING [django.request:143] Not Found: /favicon.ico
[06/Sep/2016 13:34:46] WARNING [django.request:143] Not Found: /apple-touch-icon.png
[06/Sep/2016 20:18:38] WARNING [django.request:143] Not Found: /favicon.ico
[07/Sep/2016 07:31:16] WARNING [django.request:143] Not Found: /robots.txt
[08/Sep/2016 16:03:43] WARNING [django.request:143] Not Found: /http://www.baidu.com/cache/global/img/gs.gif
[09/Sep/2016 16:59:39] WARNING [django.request:143] Not Found: /http://www.baidu.com/cache/global/img/gs.gif
[09/Sep/2016 23:09:18] WARNING [django.request:143] Not Found: /robots.txt
[11/Sep/2016 01:05:59] WARNING [django.request:143] Not Found: /http://www.baidu.com/cache/global/img/gs.gif
[11/Sep/2016 01:19:44] WARNING [django.request:143] Not Found: /favicon.ico
[13/Sep/2016 01:54:49] WARNING [django.request:143] Not Found: /favicon.ico
[13/Sep/2016 01:54:49] WARNING [django.request:143] Not Found: /apple-touch-icon-precomposed.png
[13/Sep/2016 01:54:50] WARNING [django.request:143] Not Found: /apple-touch-icon.png
[13/Sep/2016 01:54:50] WARNING [django.request:143] Not Found: /apple-touch-icon-precomposed.png
[13/Sep/2016 01:54:50] WARNING [django.request:143] Not Found: /apple-touch-icon.png
[13/Sep/2016 16:08:54] WARNING [django.request:143] Not Found: /favicon.ico
