[26/Jul/2016 13:41:31] ERROR [django.request:231] Internal Server Error: /logout
Traceback (most recent call last):
  File "/home/NANOMINE/usr/local/lib/python2.7/site-packages/django/core/handlers/base.py", line 111, in get_response
    response = wrapped_callback(request, *callback_args, **callback_kwargs)
  File "/home/NANOMINE/Develop/mdcs/mgi/views.py", line 125, in logout_view
    return redirect('/login')
  File "/home/NANOMINE/usr/local/lib/python2.7/site-packages/django/shortcuts.py", line 74, in redirect
    return redirect_class(resolve_url(to, *args, **kwargs))
  File "/home/NANOMINE/usr/local/lib/python2.7/site-packages/django/shortcuts.py", line 158, in resolve_url
    return urlresolvers.reverse(to, args=args, kwargs=kwargs)
  File "/home/NANOMINE/usr/local/lib/python2.7/site-packages/django/core/urlresolvers.py", line 546, in reverse
    return iri_to_uri(resolver._reverse_with_prefix(view, prefix, *args, **kwargs))
  File "/home/NANOMINE/usr/local/lib/python2.7/site-packages/django/core/urlresolvers.py", line 410, in _reverse_with_prefix
    self._populate()
  File "/home/NANOMINE/usr/local/lib/python2.7/site-packages/django/core/urlresolvers.py", line 303, in _populate
    lookups.appendlist(pattern.callback, (bits, p_pattern, pattern.default_args))
  File "/home/NANOMINE/usr/local/lib/python2.7/site-packages/django/core/urlresolvers.py", line 231, in callback
    self._callback = get_callable(self._callback_str)
  File "/home/NANOMINE/usr/local/lib/python2.7/site-packages/django/utils/lru_cache.py", line 101, in wrapper
    result = user_function(*args, **kwds)
  File "/home/NANOMINE/usr/local/lib/python2.7/site-packages/django/core/urlresolvers.py", line 97, in get_callable
    mod = import_module(mod_name)
  File "/home/NANOMINE/usr/local/lib/python2.7/importlib/__init__.py", line 37, in import_module
    __import__(name)
  File "/home/NANOMINE/Develop/mdcs/AUTOFIT/views.py", line 198
    else:
        ^
IndentationError: unindent does not match any outer indentation level
[26/Jul/2016 13:53:36] WARNING [django.request:143] Not Found: /favicon.ico
[26/Jul/2016 15:06:09] ERROR [django.request:231] Internal Server Error: /AUTOFITRun
Traceback (most recent call last):
  File "/home/NANOMINE/usr/local/lib/python2.7/site-packages/django/core/handlers/base.py", line 111, in get_response
    response = wrapped_callback(request, *callback_args, **callback_kwargs)
  File "/home/NANOMINE/Develop/mdcs/AUTOFIT/views.py", line 112, in runmodel
    callbin2 = "runbin('"+binary_file+"', '"+str(actuallength)+"','"+str(DiToPi)+"','"+str(vf_expt)+"'"
NameError: global name 'vf_expt' is not defined
[26/Jul/2016 15:11:03] ERROR [django.request:231] Internal Server Error: /AUTOFITRun
Traceback (most recent call last):
  File "/home/NANOMINE/usr/local/lib/python2.7/site-packages/django/core/handlers/base.py", line 111, in get_response
    response = wrapped_callback(request, *callback_args, **callback_kwargs)
  File "/home/NANOMINE/Develop/mdcs/AUTOFIT/views.py", line 112, in runmodel
    callbin2 = "runbin('"+binary_file+"', '"+str(actuallength)+"','"+str(DiToPi)+"','"+str(vf_expt)+"'"
NameError: global name 'vf_expt' is not defined
[26/Jul/2016 15:11:46] ERROR [django.request:231] Internal Server Error: /AUTOFITRun
Traceback (most recent call last):
  File "/home/NANOMINE/usr/local/lib/python2.7/site-packages/django/core/handlers/base.py", line 111, in get_response
    response = wrapped_callback(request, *callback_args, **callback_kwargs)
  File "/home/NANOMINE/Develop/mdcs/AUTOFIT/views.py", line 112, in runmodel
    callbin2 = "runbin('"+binary_file+"', '"+str(actuallength)+"','"+str(DiToPi)+"','"+str(vf_expt)+"'"
NameError: global name 'vf_expt' is not defined
[26/Jul/2016 15:13:32] WARNING [django.request:143] Not Found: /favicon.ico
[26/Jul/2016 15:57:28] WARNING [django.request:143] Not Found: /favicon.ico
[26/Jul/2016 16:22:53] ERROR [django.request:231] Internal Server Error: /AUTOFITRun
Traceback (most recent call last):
  File "/home/NANOMINE/usr/local/lib/python2.7/site-packages/django/core/handlers/base.py", line 111, in get_response
    response = wrapped_callback(request, *callback_args, **callback_kwargs)
  File "/home/NANOMINE/Develop/mdcs/AUTOFIT/views.py", line 75, in runmodel
    WorkingDir = ParentDir + timestamp + '_' + str(int(count[0]))
NameError: global name 'timestamp' is not defined
[26/Jul/2016 18:59:13] ERROR [django.request:231] Internal Server Error: /AUTOFITCheck
Traceback (most recent call last):
  File "/home/NANOMINE/usr/local/lib/python2.7/site-packages/django/core/handlers/base.py", line 111, in get_response
    response = wrapped_callback(request, *callback_args, **callback_kwargs)
  File "/home/NANOMINE/Develop/mdcs/AUTOFIT/views.py", line 201, in check
    'real_img':real_file, 'img_img':img_file, 'out_csv':out_file, 'finish':FINISH},
UnboundLocalError: local variable 'real_file' referenced before assignment
[26/Jul/2016 19:08:30] ERROR [django.request:231] Internal Server Error: /AUTOFIT/
Traceback (most recent call last):
  File "/home/NANOMINE/usr/local/lib/python2.7/site-packages/django/core/handlers/base.py", line 98, in get_response
    resolver_match = resolver.resolve(request.path_info)
  File "/home/NANOMINE/usr/local/lib/python2.7/site-packages/django/core/urlresolvers.py", line 340, in resolve
    sub_match = pattern.resolve(new_path)
  File "/home/NANOMINE/usr/local/lib/python2.7/site-packages/django/core/urlresolvers.py", line 224, in resolve
    return ResolverMatch(self.callback, args, kwargs, self.name)
  File "/home/NANOMINE/usr/local/lib/python2.7/site-packages/django/core/urlresolvers.py", line 231, in callback
    self._callback = get_callable(self._callback_str)
  File "/home/NANOMINE/usr/local/lib/python2.7/site-packages/django/utils/lru_cache.py", line 101, in wrapper
    result = user_function(*args, **kwds)
  File "/home/NANOMINE/usr/local/lib/python2.7/site-packages/django/core/urlresolvers.py", line 97, in get_callable
    mod = import_module(mod_name)
  File "/home/NANOMINE/usr/local/lib/python2.7/importlib/__init__.py", line 37, in import_module
    __import__(name)
  File "/home/NANOMINE/Develop/mdcs/AUTOFIT/views.py", line 135
    callopt = "cd "+WorkingDir+";"+
                                  ^
SyntaxError: invalid syntax
[26/Jul/2016 19:43:17] WARNING [django.request:143] Not Found: /favicon.ico
[27/Jul/2016 00:06:27] WARNING [django.request:143] Not Found: /favicon.ico
[27/Jul/2016 05:32:35] WARNING [django.request:143] Not Found: /robots.txt
[27/Jul/2016 14:53:27] WARNING [django.request:143] Not Found: /favicon.ico
[27/Jul/2016 15:10:29] DEBUG [oauthlib.oauth2.rfc6749.endpoints.resource:74] Dispatching token_type Bearer request to <oauthlib.oauth2.rfc6749.tokens.BearerToken object at 0x7fed801bdb90>.
[27/Jul/2016 15:10:43] DEBUG [oauthlib.oauth2.rfc6749.endpoints.resource:74] Dispatching token_type Bearer request to <oauthlib.oauth2.rfc6749.tokens.BearerToken object at 0x7fed801bdb50>.
[27/Jul/2016 15:10:47] DEBUG [oauthlib.oauth2.rfc6749.endpoints.resource:74] Dispatching token_type Bearer request to <oauthlib.oauth2.rfc6749.tokens.BearerToken object at 0x7fed8018d150>.
[27/Jul/2016 15:10:48] DEBUG [oauthlib.oauth2.rfc6749.endpoints.resource:74] Dispatching token_type Bearer request to <oauthlib.oauth2.rfc6749.tokens.BearerToken object at 0x7fed801bf810>.
[27/Jul/2016 15:10:51] DEBUG [oauthlib.oauth2.rfc6749.endpoints.resource:74] Dispatching token_type Bearer request to <oauthlib.oauth2.rfc6749.tokens.BearerToken object at 0x7fed801bdd90>.
[27/Jul/2016 15:10:56] DEBUG [oauthlib.oauth2.rfc6749.endpoints.resource:74] Dispatching token_type Bearer request to <oauthlib.oauth2.rfc6749.tokens.BearerToken object at 0x7fed989a40d0>.
[27/Jul/2016 15:25:00] DEBUG [oauthlib.oauth2.rfc6749.endpoints.resource:74] Dispatching token_type Bearer request to <oauthlib.oauth2.rfc6749.tokens.BearerToken object at 0x7fed84803490>.
[27/Jul/2016 16:21:32] DEBUG [oauthlib.oauth2.rfc6749.endpoints.resource:74] Dispatching token_type Bearer request to <oauthlib.oauth2.rfc6749.tokens.BearerToken object at 0x7fed8481af10>.
[27/Jul/2016 17:10:26] ERROR [django.request:231] Internal Server Error: /curate/generate
Traceback (most recent call last):
  File "/home/NANOMINE/usr/local/lib/python2.7/site-packages/django/core/handlers/base.py", line 111, in get_response
    response = wrapped_callback(request, *callback_args, **callback_kwargs)
  File "/home/NANOMINE/Develop/mdcs/curate/ajax.py", line 1508, in generate_absent
    form_data_id = request.session['curateFormData']
  File "/home/NANOMINE/usr/local/lib/python2.7/site-packages/django/contrib/sessions/backends/base.py", line 49, in __getitem__
    return self._session[key]
KeyError: 'curateFormData'
[27/Jul/2016 17:10:31] ERROR [django.request:231] Internal Server Error: /curate/generate
Traceback (most recent call last):
  File "/home/NANOMINE/usr/local/lib/python2.7/site-packages/django/core/handlers/base.py", line 111, in get_response
    response = wrapped_callback(request, *callback_args, **callback_kwargs)
  File "/home/NANOMINE/Develop/mdcs/curate/ajax.py", line 1508, in generate_absent
    form_data_id = request.session['curateFormData']
  File "/home/NANOMINE/usr/local/lib/python2.7/site-packages/django/contrib/sessions/backends/base.py", line 49, in __getitem__
    return self._session[key]
KeyError: 'curateFormData'
[27/Jul/2016 17:10:32] ERROR [django.request:231] Internal Server Error: /curate/generate
Traceback (most recent call last):
  File "/home/NANOMINE/usr/local/lib/python2.7/site-packages/django/core/handlers/base.py", line 111, in get_response
    response = wrapped_callback(request, *callback_args, **callback_kwargs)
  File "/home/NANOMINE/Develop/mdcs/curate/ajax.py", line 1508, in generate_absent
    form_data_id = request.session['curateFormData']
  File "/home/NANOMINE/usr/local/lib/python2.7/site-packages/django/contrib/sessions/backends/base.py", line 49, in __getitem__
    return self._session[key]
KeyError: 'curateFormData'
[27/Jul/2016 17:10:35] ERROR [django.request:231] Internal Server Error: /curate/generate
Traceback (most recent call last):
  File "/home/NANOMINE/usr/local/lib/python2.7/site-packages/django/core/handlers/base.py", line 111, in get_response
    response = wrapped_callback(request, *callback_args, **callback_kwargs)
  File "/home/NANOMINE/Develop/mdcs/curate/ajax.py", line 1508, in generate_absent
    form_data_id = request.session['curateFormData']
  File "/home/NANOMINE/usr/local/lib/python2.7/site-packages/django/contrib/sessions/backends/base.py", line 49, in __getitem__
    return self._session[key]
KeyError: 'curateFormData'
[27/Jul/2016 17:10:38] ERROR [django.request:231] Internal Server Error: /curate/save_form
Traceback (most recent call last):
  File "/home/NANOMINE/usr/local/lib/python2.7/site-packages/django/core/handlers/base.py", line 111, in get_response
    response = wrapped_callback(request, *callback_args, **callback_kwargs)
  File "/home/NANOMINE/Develop/mdcs/curate/ajax.py", line 78, in save_form
    form_data_id = request.session['curateFormData']
  File "/home/NANOMINE/usr/local/lib/python2.7/site-packages/django/contrib/sessions/backends/base.py", line 49, in __getitem__
    return self._session[key]
KeyError: 'curateFormData'
[27/Jul/2016 17:11:35] ERROR [django.request:231] Internal Server Error: /curate/generate
Traceback (most recent call last):
  File "/home/NANOMINE/usr/local/lib/python2.7/site-packages/django/core/handlers/base.py", line 111, in get_response
    response = wrapped_callback(request, *callback_args, **callback_kwargs)
  File "/home/NANOMINE/Develop/mdcs/curate/ajax.py", line 1508, in generate_absent
    form_data_id = request.session['curateFormData']
  File "/home/NANOMINE/usr/local/lib/python2.7/site-packages/django/contrib/sessions/backends/base.py", line 49, in __getitem__
    return self._session[key]
KeyError: 'curateFormData'
[27/Jul/2016 17:11:36] ERROR [django.request:231] Internal Server Error: /curate/generate
Traceback (most recent call last):
  File "/home/NANOMINE/usr/local/lib/python2.7/site-packages/django/core/handlers/base.py", line 111, in get_response
    response = wrapped_callback(request, *callback_args, **callback_kwargs)
  File "/home/NANOMINE/Develop/mdcs/curate/ajax.py", line 1508, in generate_absent
    form_data_id = request.session['curateFormData']
  File "/home/NANOMINE/usr/local/lib/python2.7/site-packages/django/contrib/sessions/backends/base.py", line 49, in __getitem__
    return self._session[key]
KeyError: 'curateFormData'
[27/Jul/2016 17:11:36] ERROR [django.request:231] Internal Server Error: /curate/generate
Traceback (most recent call last):
  File "/home/NANOMINE/usr/local/lib/python2.7/site-packages/django/core/handlers/base.py", line 111, in get_response
    response = wrapped_callback(request, *callback_args, **callback_kwargs)
  File "/home/NANOMINE/Develop/mdcs/curate/ajax.py", line 1508, in generate_absent
    form_data_id = request.session['curateFormData']
  File "/home/NANOMINE/usr/local/lib/python2.7/site-packages/django/contrib/sessions/backends/base.py", line 49, in __getitem__
    return self._session[key]
KeyError: 'curateFormData'
[27/Jul/2016 17:11:36] ERROR [django.request:231] Internal Server Error: /curate/generate
Traceback (most recent call last):
  File "/home/NANOMINE/usr/local/lib/python2.7/site-packages/django/core/handlers/base.py", line 111, in get_response
    response = wrapped_callback(request, *callback_args, **callback_kwargs)
  File "/home/NANOMINE/Develop/mdcs/curate/ajax.py", line 1508, in generate_absent
    form_data_id = request.session['curateFormData']
  File "/home/NANOMINE/usr/local/lib/python2.7/site-packages/django/contrib/sessions/backends/base.py", line 49, in __getitem__
    return self._session[key]
KeyError: 'curateFormData'
[27/Jul/2016 17:11:36] ERROR [django.request:231] Internal Server Error: /curate/generate
Traceback (most recent call last):
  File "/home/NANOMINE/usr/local/lib/python2.7/site-packages/django/core/handlers/base.py", line 111, in get_response
    response = wrapped_callback(request, *callback_args, **callback_kwargs)
  File "/home/NANOMINE/Develop/mdcs/curate/ajax.py", line 1508, in generate_absent
    form_data_id = request.session['curateFormData']
  File "/home/NANOMINE/usr/local/lib/python2.7/site-packages/django/contrib/sessions/backends/base.py", line 49, in __getitem__
    return self._session[key]
KeyError: 'curateFormData'
[27/Jul/2016 17:11:36] ERROR [django.request:231] Internal Server Error: /curate/generate
Traceback (most recent call last):
  File "/home/NANOMINE/usr/local/lib/python2.7/site-packages/django/core/handlers/base.py", line 111, in get_response
    response = wrapped_callback(request, *callback_args, **callback_kwargs)
  File "/home/NANOMINE/Develop/mdcs/curate/ajax.py", line 1508, in generate_absent
    form_data_id = request.session['curateFormData']
  File "/home/NANOMINE/usr/local/lib/python2.7/site-packages/django/contrib/sessions/backends/base.py", line 49, in __getitem__
    return self._session[key]
KeyError: 'curateFormData'
[27/Jul/2016 17:11:37] ERROR [django.request:231] Internal Server Error: /curate/generate
Traceback (most recent call last):
  File "/home/NANOMINE/usr/local/lib/python2.7/site-packages/django/core/handlers/base.py", line 111, in get_response
    response = wrapped_callback(request, *callback_args, **callback_kwargs)
  File "/home/NANOMINE/Develop/mdcs/curate/ajax.py", line 1508, in generate_absent
    form_data_id = request.session['curateFormData']
  File "/home/NANOMINE/usr/local/lib/python2.7/site-packages/django/contrib/sessions/backends/base.py", line 49, in __getitem__
    return self._session[key]
KeyError: 'curateFormData'
[27/Jul/2016 17:11:37] ERROR [django.request:231] Internal Server Error: /curate/generate
Traceback (most recent call last):
  File "/home/NANOMINE/usr/local/lib/python2.7/site-packages/django/core/handlers/base.py", line 111, in get_response
    response = wrapped_callback(request, *callback_args, **callback_kwargs)
  File "/home/NANOMINE/Develop/mdcs/curate/ajax.py", line 1508, in generate_absent
    form_data_id = request.session['curateFormData']
  File "/home/NANOMINE/usr/local/lib/python2.7/site-packages/django/contrib/sessions/backends/base.py", line 49, in __getitem__
    return self._session[key]
KeyError: 'curateFormData'
[27/Jul/2016 17:11:39] ERROR [django.request:231] Internal Server Error: /curate/generate
Traceback (most recent call last):
  File "/home/NANOMINE/usr/local/lib/python2.7/site-packages/django/core/handlers/base.py", line 111, in get_response
    response = wrapped_callback(request, *callback_args, **callback_kwargs)
  File "/home/NANOMINE/Develop/mdcs/curate/ajax.py", line 1508, in generate_absent
    form_data_id = request.session['curateFormData']
  File "/home/NANOMINE/usr/local/lib/python2.7/site-packages/django/contrib/sessions/backends/base.py", line 49, in __getitem__
    return self._session[key]
KeyError: 'curateFormData'
[27/Jul/2016 17:21:38] WARNING [django.request:143] Not Found: /favicon.ico
[27/Jul/2016 19:39:10] WARNING [django.request:143] Not Found: /favicon.ico
[28/Jul/2016 00:02:02] WARNING [django.request:143] Not Found: /favicon.ico
[28/Jul/2016 01:46:11] WARNING [django.request:143] Not Found: /favicon.ico
[28/Jul/2016 13:34:30] WARNING [django.request:143] Not Found: /favicon.ico
[28/Jul/2016 13:56:08] WARNING [django.request:143] Not Found: /favicon.ico
[28/Jul/2016 14:22:18] ERROR [django.request:231] Internal Server Error: /RECONCheck
Traceback (most recent call last):
  File "/home/NANOMINE/usr/local/lib/python2.7/site-packages/django/core/handlers/base.py", line 111, in get_response
    response = wrapped_callback(request, *callback_args, **callback_kwargs)
  File "/home/NANOMINE/Develop/mdcs/RECON/views.py", line 174, in check
    'out8':out8, 'finish':FINISH, 'type':ttype},
NameError: global name 'ttype' is not defined
[28/Jul/2016 16:55:44] WARNING [django.request:143] Not Found: /http://www.baidu.com/cache/global/img/gs.gif
[28/Jul/2016 17:17:50] DEBUG [oauthlib.oauth2.rfc6749.endpoints.resource:74] Dispatching token_type Bearer request to <oauthlib.oauth2.rfc6749.tokens.BearerToken object at 0x7fed80195e10>.
[28/Jul/2016 17:17:50] DEBUG [oauthlib.oauth2.rfc6749.endpoints.resource:74] Dispatching token_type Bearer request to <oauthlib.oauth2.rfc6749.tokens.BearerToken object at 0x7fed80195f50>.
[28/Jul/2016 17:20:50] DEBUG [oauthlib.oauth2.rfc6749.endpoints.resource:74] Dispatching token_type Bearer request to <oauthlib.oauth2.rfc6749.tokens.BearerToken object at 0x7fed8d91f850>.
[28/Jul/2016 17:20:57] DEBUG [oauthlib.oauth2.rfc6749.endpoints.resource:74] Dispatching token_type Bearer request to <oauthlib.oauth2.rfc6749.tokens.BearerToken object at 0x7fed8c673a90>.
[28/Jul/2016 17:21:01] DEBUG [oauthlib.oauth2.rfc6749.endpoints.resource:74] Dispatching token_type Bearer request to <oauthlib.oauth2.rfc6749.tokens.BearerToken object at 0x7fed80195d90>.
[28/Jul/2016 17:21:03] DEBUG [oauthlib.oauth2.rfc6749.endpoints.resource:74] Dispatching token_type Bearer request to <oauthlib.oauth2.rfc6749.tokens.BearerToken object at 0x7fed80195650>.
[28/Jul/2016 17:21:08] DEBUG [oauthlib.oauth2.rfc6749.endpoints.resource:74] Dispatching token_type Bearer request to <oauthlib.oauth2.rfc6749.tokens.BearerToken object at 0x7fed8c66b590>.
[28/Jul/2016 17:43:40] DEBUG [oauthlib.oauth2.rfc6749.endpoints.resource:74] Dispatching token_type Bearer request to <oauthlib.oauth2.rfc6749.tokens.BearerToken object at 0x7fed812ccc90>.
[28/Jul/2016 17:43:41] DEBUG [oauthlib.oauth2.rfc6749.endpoints.resource:74] Dispatching token_type Bearer request to <oauthlib.oauth2.rfc6749.tokens.BearerToken object at 0x7fed8c6719d0>.
[28/Jul/2016 17:43:45] DEBUG [oauthlib.oauth2.rfc6749.endpoints.resource:74] Dispatching token_type Bearer request to <oauthlib.oauth2.rfc6749.tokens.BearerToken object at 0x7fed846dad50>.
[28/Jul/2016 17:43:46] DEBUG [oauthlib.oauth2.rfc6749.endpoints.resource:74] Dispatching token_type Bearer request to <oauthlib.oauth2.rfc6749.tokens.BearerToken object at 0x7fed801c15d0>.
[28/Jul/2016 17:43:47] DEBUG [oauthlib.oauth2.rfc6749.endpoints.resource:74] Dispatching token_type Bearer request to <oauthlib.oauth2.rfc6749.tokens.BearerToken object at 0x7fed845911d0>.
[28/Jul/2016 17:43:49] DEBUG [oauthlib.oauth2.rfc6749.endpoints.resource:74] Dispatching token_type Bearer request to <oauthlib.oauth2.rfc6749.tokens.BearerToken object at 0x7fed8c671810>.
[28/Jul/2016 17:49:37] WARNING [django.request:143] Not Found: /favicon.ico
[28/Jul/2016 17:49:37] WARNING [django.request:143] Not Found: /apple-touch-icon-precomposed.png
[28/Jul/2016 17:49:37] WARNING [django.request:143] Not Found: /apple-touch-icon.png
[28/Jul/2016 18:19:30] ERROR [django.request:231] Internal Server Error: /MCFEA/MCFEAValidateInput
Traceback (most recent call last):
  File "/home/NANOMINE/usr/local/lib/python2.7/site-packages/django/core/handlers/base.py", line 111, in get_response
    response = wrapped_callback(request, *callback_args, **callback_kwargs)
  File "/home/NANOMINE/Develop/mdcs/MCFEA/views.py", line 60, in validate
    out1['Nominal field'] = field
NameError: global name 'field' is not defined
[28/Jul/2016 18:27:56] ERROR [django.request:231] Internal Server Error: /RECONCheck
Traceback (most recent call last):
  File "/home/NANOMINE/usr/local/lib/python2.7/site-packages/django/core/handlers/base.py", line 111, in get_response
    response = wrapped_callback(request, *callback_args, **callback_kwargs)
  File "/home/NANOMINE/Develop/mdcs/RECON/views.py", line 190, in check
    'out8':out8, 'finish':FINISH, 'type':TYPE},
UnboundLocalError: local variable 'TYPE' referenced before assignment
[28/Jul/2016 18:29:09] ERROR [django.request:231] Internal Server Error: /RECONCheck
Traceback (most recent call last):
  File "/home/NANOMINE/usr/local/lib/python2.7/site-packages/django/core/handlers/base.py", line 111, in get_response
    response = wrapped_callback(request, *callback_args, **callback_kwargs)
  File "/home/NANOMINE/Develop/mdcs/RECON/views.py", line 190, in check
    'out8':out8, 'finish':FINISH, 'type':TYPE},
UnboundLocalError: local variable 'TYPE' referenced before assignment
[28/Jul/2016 18:53:01] ERROR [django.request:231] Internal Server Error: /RECONCheck
Traceback (most recent call last):
  File "/home/NANOMINE/usr/local/lib/python2.7/site-packages/django/core/handlers/base.py", line 111, in get_response
    response = wrapped_callback(request, *callback_args, **callback_kwargs)
  File "/home/NANOMINE/Develop/mdcs/RECON/views.py", line 173, in check
    cpcp = 'cp '+WorkingDir+'/'+FILE+'_results/* '+ApacheCaseDir
NameError: global name 'WorkingDir' is not defined
[28/Jul/2016 19:03:19] ERROR [django.request:231] Internal Server Error: /RECONCheck
Traceback (most recent call last):
  File "/home/NANOMINE/usr/local/lib/python2.7/site-packages/django/core/handlers/base.py", line 111, in get_response
    response = wrapped_callback(request, *callback_args, **callback_kwargs)
  File "/home/NANOMINE/Develop/mdcs/RECON/views.py", line 173, in check
    cpcp = 'cp '+WorkingDir+'/'+FILE+'_results/* '+ApacheCaseDir
NameError: global name 'WorkingDir' is not defined
[28/Jul/2016 19:11:40] ERROR [django.request:231] Internal Server Error: /MCFEA/MCFEAValidateInput
Traceback (most recent call last):
  File "/home/NANOMINE/usr/local/lib/python2.7/site-packages/django/core/handlers/base.py", line 111, in get_response
    response = wrapped_callback(request, *callback_args, **callback_kwargs)
  File "/home/NANOMINE/Develop/mdcs/MCFEA/views.py", line 60, in validate
    out1['Nominal field'] = field
NameError: global name 'field' is not defined
[28/Jul/2016 19:56:55] ERROR [django.request:231] Internal Server Error: /curate/generate_xsd_form
Traceback (most recent call last):
  File "/home/NANOMINE/usr/local/lib/python2.7/site-packages/django/core/handlers/base.py", line 111, in get_response
    response = wrapped_callback(request, *callback_args, **callback_kwargs)
  File "/home/NANOMINE/Develop/mdcs/curate/ajax.py", line 2051, in generate_xsd_form
    formString += generateForm(request)
  File "/home/NANOMINE/Develop/mdcs/curate/ajax.py", line 1948, in generateForm
    edit_data_tree = etree.XML(str(form_data.xml_data))
UnicodeEncodeError: 'ascii' codec can't encode character u'\u2212' in position 370: ordinal not in range(128)
[28/Jul/2016 19:58:11] ERROR [django.request:231] Internal Server Error: /curate/generate_xsd_form
Traceback (most recent call last):
  File "/home/NANOMINE/usr/local/lib/python2.7/site-packages/django/core/handlers/base.py", line 111, in get_response
    response = wrapped_callback(request, *callback_args, **callback_kwargs)
  File "/home/NANOMINE/Develop/mdcs/curate/ajax.py", line 2051, in generate_xsd_form
    formString += generateForm(request)
  File "/home/NANOMINE/Develop/mdcs/curate/ajax.py", line 1948, in generateForm
    edit_data_tree = etree.XML(str(form_data.xml_data))
UnicodeEncodeError: 'ascii' codec can't encode character u'\u2212' in position 370: ordinal not in range(128)
[28/Jul/2016 19:58:29] ERROR [django.request:231] Internal Server Error: /curate/generate_xsd_form
Traceback (most recent call last):
  File "/home/NANOMINE/usr/local/lib/python2.7/site-packages/django/core/handlers/base.py", line 111, in get_response
    response = wrapped_callback(request, *callback_args, **callback_kwargs)
  File "/home/NANOMINE/Develop/mdcs/curate/ajax.py", line 2051, in generate_xsd_form
    formString += generateForm(request)
  File "/home/NANOMINE/Develop/mdcs/curate/ajax.py", line 1948, in generateForm
    edit_data_tree = etree.XML(str(form_data.xml_data))
UnicodeEncodeError: 'ascii' codec can't encode character u'\u2212' in position 370: ordinal not in range(128)
[28/Jul/2016 19:58:49] ERROR [django.request:231] Internal Server Error: /curate/generate_xsd_form
Traceback (most recent call last):
  File "/home/NANOMINE/usr/local/lib/python2.7/site-packages/django/core/handlers/base.py", line 111, in get_response
    response = wrapped_callback(request, *callback_args, **callback_kwargs)
  File "/home/NANOMINE/Develop/mdcs/curate/ajax.py", line 2051, in generate_xsd_form
    formString += generateForm(request)
  File "/home/NANOMINE/Develop/mdcs/curate/ajax.py", line 1948, in generateForm
    edit_data_tree = etree.XML(str(form_data.xml_data))
UnicodeEncodeError: 'ascii' codec can't encode character u'\u2212' in position 370: ordinal not in range(128)
[28/Jul/2016 19:58:57] ERROR [django.request:231] Internal Server Error: /curate/validate_xml_data
Traceback (most recent call last):
  File "/home/NANOMINE/usr/local/lib/python2.7/site-packages/django/core/handlers/base.py", line 111, in get_response
    response = wrapped_callback(request, *callback_args, **callback_kwargs)
  File "/home/NANOMINE/Develop/mdcs/curate/ajax.py", line 107, in validate_xml_data
    message= e.message.replace('"', '\'')
AttributeError: 'NoneType' object has no attribute 'replace'
[28/Jul/2016 19:59:13] ERROR [django.request:231] Internal Server Error: /curate/generate_xsd_form
Traceback (most recent call last):
  File "/home/NANOMINE/usr/local/lib/python2.7/site-packages/django/core/handlers/base.py", line 111, in get_response
    response = wrapped_callback(request, *callback_args, **callback_kwargs)
  File "/home/NANOMINE/Develop/mdcs/curate/ajax.py", line 2051, in generate_xsd_form
    formString += generateForm(request)
  File "/home/NANOMINE/Develop/mdcs/curate/ajax.py", line 1948, in generateForm
    edit_data_tree = etree.XML(str(form_data.xml_data))
UnicodeEncodeError: 'ascii' codec can't encode character u'\u2212' in position 370: ordinal not in range(128)
[28/Jul/2016 20:00:23] ERROR [django.request:231] Internal Server Error: /curate/generate_xsd_form
Traceback (most recent call last):
  File "/home/NANOMINE/usr/local/lib/python2.7/site-packages/django/core/handlers/base.py", line 111, in get_response
    response = wrapped_callback(request, *callback_args, **callback_kwargs)
  File "/home/NANOMINE/Develop/mdcs/curate/ajax.py", line 2051, in generate_xsd_form
    formString += generateForm(request)
  File "/home/NANOMINE/Develop/mdcs/curate/ajax.py", line 1948, in generateForm
    edit_data_tree = etree.XML(str(form_data.xml_data))
UnicodeEncodeError: 'ascii' codec can't encode character u'\u2212' in position 370: ordinal not in range(128)
[28/Jul/2016 20:01:13] ERROR [django.request:231] Internal Server Error: /curate/validate_xml_data
Traceback (most recent call last):
  File "/home/NANOMINE/usr/local/lib/python2.7/site-packages/django/core/handlers/base.py", line 111, in get_response
    response = wrapped_callback(request, *callback_args, **callback_kwargs)
  File "/home/NANOMINE/Develop/mdcs/curate/ajax.py", line 107, in validate_xml_data
    message= e.message.replace('"', '\'')
AttributeError: 'NoneType' object has no attribute 'replace'
[28/Jul/2016 20:01:16] ERROR [django.request:231] Internal Server Error: /curate/validate_xml_data
Traceback (most recent call last):
  File "/home/NANOMINE/usr/local/lib/python2.7/site-packages/django/core/handlers/base.py", line 111, in get_response
    response = wrapped_callback(request, *callback_args, **callback_kwargs)
  File "/home/NANOMINE/Develop/mdcs/curate/ajax.py", line 107, in validate_xml_data
    message= e.message.replace('"', '\'')
AttributeError: 'NoneType' object has no attribute 'replace'
[28/Jul/2016 20:01:20] ERROR [django.request:231] Internal Server Error: /curate/validate_xml_data
Traceback (most recent call last):
  File "/home/NANOMINE/usr/local/lib/python2.7/site-packages/django/core/handlers/base.py", line 111, in get_response
    response = wrapped_callback(request, *callback_args, **callback_kwargs)
  File "/home/NANOMINE/Develop/mdcs/curate/ajax.py", line 107, in validate_xml_data
    message= e.message.replace('"', '\'')
AttributeError: 'NoneType' object has no attribute 'replace'
[28/Jul/2016 20:01:20] ERROR [django.request:231] Internal Server Error: /curate/validate_xml_data
Traceback (most recent call last):
  File "/home/NANOMINE/usr/local/lib/python2.7/site-packages/django/core/handlers/base.py", line 111, in get_response
    response = wrapped_callback(request, *callback_args, **callback_kwargs)
  File "/home/NANOMINE/Develop/mdcs/curate/ajax.py", line 107, in validate_xml_data
    message= e.message.replace('"', '\'')
AttributeError: 'NoneType' object has no attribute 'replace'
[28/Jul/2016 20:01:20] ERROR [django.request:231] Internal Server Error: /curate/validate_xml_data
Traceback (most recent call last):
  File "/home/NANOMINE/usr/local/lib/python2.7/site-packages/django/core/handlers/base.py", line 111, in get_response
    response = wrapped_callback(request, *callback_args, **callback_kwargs)
  File "/home/NANOMINE/Develop/mdcs/curate/ajax.py", line 107, in validate_xml_data
    message= e.message.replace('"', '\'')
AttributeError: 'NoneType' object has no attribute 'replace'
[28/Jul/2016 20:01:21] ERROR [django.request:231] Internal Server Error: /curate/validate_xml_data
Traceback (most recent call last):
  File "/home/NANOMINE/usr/local/lib/python2.7/site-packages/django/core/handlers/base.py", line 111, in get_response
    response = wrapped_callback(request, *callback_args, **callback_kwargs)
  File "/home/NANOMINE/Develop/mdcs/curate/ajax.py", line 107, in validate_xml_data
    message= e.message.replace('"', '\'')
AttributeError: 'NoneType' object has no attribute 'replace'
[28/Jul/2016 20:01:22] ERROR [django.request:231] Internal Server Error: /curate/validate_xml_data
Traceback (most recent call last):
  File "/home/NANOMINE/usr/local/lib/python2.7/site-packages/django/core/handlers/base.py", line 111, in get_response
    response = wrapped_callback(request, *callback_args, **callback_kwargs)
  File "/home/NANOMINE/Develop/mdcs/curate/ajax.py", line 107, in validate_xml_data
    message= e.message.replace('"', '\'')
AttributeError: 'NoneType' object has no attribute 'replace'
[28/Jul/2016 20:02:31] ERROR [django.request:231] Internal Server Error: /curate/generate_xsd_form
Traceback (most recent call last):
  File "/home/NANOMINE/usr/local/lib/python2.7/site-packages/django/core/handlers/base.py", line 111, in get_response
    response = wrapped_callback(request, *callback_args, **callback_kwargs)
  File "/home/NANOMINE/Develop/mdcs/curate/ajax.py", line 2051, in generate_xsd_form
    formString += generateForm(request)
  File "/home/NANOMINE/Develop/mdcs/curate/ajax.py", line 1948, in generateForm
    edit_data_tree = etree.XML(str(form_data.xml_data))
UnicodeEncodeError: 'ascii' codec can't encode character u'\u2212' in position 370: ordinal not in range(128)
[28/Jul/2016 20:03:03] ERROR [django.request:231] Internal Server Error: /curate/generate_xsd_form
Traceback (most recent call last):
  File "/home/NANOMINE/usr/local/lib/python2.7/site-packages/django/core/handlers/base.py", line 111, in get_response
    response = wrapped_callback(request, *callback_args, **callback_kwargs)
  File "/home/NANOMINE/Develop/mdcs/curate/ajax.py", line 2051, in generate_xsd_form
    formString += generateForm(request)
  File "/home/NANOMINE/Develop/mdcs/curate/ajax.py", line 1948, in generateForm
    edit_data_tree = etree.XML(str(form_data.xml_data))
  File "lxml.etree.pyx", line 3072, in lxml.etree.XML (src/lxml/lxml.etree.c:70242)
  File "parser.pxi", line 1828, in lxml.etree._parseMemoryDocument (src/lxml/lxml.etree.c:106307)
  File "parser.pxi", line 1716, in lxml.etree._parseDoc (src/lxml/lxml.etree.c:105098)
  File "parser.pxi", line 1086, in lxml.etree._BaseParser._parseDoc (src/lxml/lxml.etree.c:99780)
  File "parser.pxi", line 580, in lxml.etree._ParserContext._handleParseResultDoc (src/lxml/lxml.etree.c:94254)
  File "parser.pxi", line 690, in lxml.etree._handleParseResult (src/lxml/lxml.etree.c:95690)
  File "parser.pxi", line 631, in lxml.etree._raiseParseError (src/lxml/lxml.etree.c:94969)
XMLSyntaxError: None
[28/Jul/2016 20:03:26] ERROR [django.request:231] Internal Server Error: /curate/validate_xml_data
Traceback (most recent call last):
  File "/home/NANOMINE/usr/local/lib/python2.7/site-packages/django/core/handlers/base.py", line 111, in get_response
    response = wrapped_callback(request, *callback_args, **callback_kwargs)
  File "/home/NANOMINE/Develop/mdcs/curate/ajax.py", line 107, in validate_xml_data
    message= e.message.replace('"', '\'')
AttributeError: 'NoneType' object has no attribute 'replace'
[28/Jul/2016 20:03:43] ERROR [django.request:231] Internal Server Error: /curate/generate_xsd_form
Traceback (most recent call last):
  File "/home/NANOMINE/usr/local/lib/python2.7/site-packages/django/core/handlers/base.py", line 111, in get_response
    response = wrapped_callback(request, *callback_args, **callback_kwargs)
  File "/home/NANOMINE/Develop/mdcs/curate/ajax.py", line 2051, in generate_xsd_form
    formString += generateForm(request)
  File "/home/NANOMINE/Develop/mdcs/curate/ajax.py", line 1948, in generateForm
    edit_data_tree = etree.XML(str(form_data.xml_data))
UnicodeEncodeError: 'ascii' codec can't encode character u'\u2212' in position 370: ordinal not in range(128)
[28/Jul/2016 23:25:10] WARNING [django.request:143] Not Found: /favicon.ico
[28/Jul/2016 23:57:51] ERROR [django.request:231] Internal Server Error: /curate/generate_xsd_form
Traceback (most recent call last):
  File "/home/NANOMINE/usr/local/lib/python2.7/site-packages/django/core/handlers/base.py", line 111, in get_response
    response = wrapped_callback(request, *callback_args, **callback_kwargs)
  File "/home/NANOMINE/Develop/mdcs/curate/ajax.py", line 2051, in generate_xsd_form
    formString += generateForm(request)
  File "/home/NANOMINE/Develop/mdcs/curate/ajax.py", line 1948, in generateForm
    edit_data_tree = etree.XML(str(form_data.xml_data))
UnicodeEncodeError: 'ascii' codec can't encode character u'\ufeff' in position 0: ordinal not in range(128)
[29/Jul/2016 00:34:23] WARNING [django.request:143] Not Found: /http://www.baidu.com/cache/global/img/gs.gif
[29/Jul/2016 11:51:55] WARNING [django.request:143] Not Found: /robots.txt
[29/Jul/2016 14:30:00] WARNING [django.request:143] Not Found: /apple-touch-icon-precomposed.png
[29/Jul/2016 14:30:00] WARNING [django.request:143] Not Found: /favicon.ico
[29/Jul/2016 14:30:00] WARNING [django.request:143] Not Found: /apple-touch-icon.png
[29/Jul/2016 14:40:29] WARNING [django.request:143] Not Found: /apple-touch-icon-precomposed.png
[29/Jul/2016 14:40:29] WARNING [django.request:143] Not Found: /favicon.ico
[29/Jul/2016 14:40:30] WARNING [django.request:143] Not Found: /apple-touch-icon.png
[29/Jul/2016 14:40:31] WARNING [django.request:143] Not Found: /apple-touch-icon-precomposed.png
[29/Jul/2016 14:40:33] WARNING [django.request:143] Not Found: /apple-touch-icon.png
[29/Jul/2016 15:09:02] WARNING [django.request:143] Not Found: /c/
[29/Jul/2016 15:11:54] WARNING [django.request:143] Not Found: /apple-touch-icon-precomposed.png
[29/Jul/2016 15:11:54] WARNING [django.request:143] Not Found: /apple-touch-icon.png
[29/Jul/2016 15:52:05] WARNING [django.request:143] Not Found: /favicon.ico
[29/Jul/2016 23:50:35] WARNING [django.request:143] Not Found: /c/
[30/Jul/2016 02:45:39] WARNING [django.request:143] Not Found: /favicon.ico
[30/Jul/2016 04:39:25] WARNING [django.request:143] Not Found: /favicon.ico
[30/Jul/2016 06:24:19] WARNING [django.request:143] Not Found: /apple-touch-icon-120x120-precomposed.png
[30/Jul/2016 06:24:20] WARNING [django.request:143] Not Found: /apple-touch-icon-120x120.png
[30/Jul/2016 06:24:20] WARNING [django.request:143] Not Found: /apple-touch-icon.png
[30/Jul/2016 06:24:20] WARNING [django.request:143] Not Found: /apple-touch-icon.png
[30/Jul/2016 06:24:20] WARNING [django.request:143] Not Found: /apple-touch-icon-precomposed.png
[30/Jul/2016 06:24:20] WARNING [django.request:143] Not Found: /favicon.ico
[30/Jul/2016 22:43:50] WARNING [django.request:143] Not Found: /favicon.ico
[30/Jul/2016 22:43:50] WARNING [django.request:143] Not Found: /apple-touch-icon-precomposed.png
[30/Jul/2016 22:43:50] WARNING [django.request:143] Not Found: /apple-touch-icon.png
[30/Jul/2016 22:43:51] WARNING [django.request:143] Not Found: /apple-touch-icon-precomposed.png
[30/Jul/2016 22:43:51] WARNING [django.request:143] Not Found: /apple-touch-icon.png
[31/Jul/2016 15:34:05] WARNING [django.request:143] Not Found: /favicon.ico
[01/Aug/2016 00:36:05] WARNING [django.request:143] Not Found: /favicon.ico
[01/Aug/2016 00:37:07] WARNING [django.request:143] Not Found: /favicon.ico
[01/Aug/2016 01:32:25] WARNING [django.request:143] Not Found: /http://www.baidu.com/cache/global/img/gs.gif
[01/Aug/2016 02:59:54] WARNING [django.request:143] Not Found: /favicon.ico
[01/Aug/2016 13:41:46] WARNING [django.request:143] Not Found: /favicon.ico
[01/Aug/2016 16:36:34] ERROR [django.request:231] Internal Server Error: /modules/diffusion/upload-excel
Traceback (most recent call last):
  File "/home/NANOMINE/usr/local/lib/python2.7/site-packages/django/core/handlers/base.py", line 111, in get_response
    response = wrapped_callback(request, *callback_args, **callback_kwargs)
  File "/home/NANOMINE/Develop/mdcs/modules/diffusion/views.py", line 13, in upload_excel_view
    return ExcelUploaderModule().render(request)
  File "/home/NANOMINE/Develop/mdcs/modules/models.py", line 37, in render
    return self._post(request)
  File "/home/NANOMINE/Develop/mdcs/modules/models.py", line 82, in _post
    raise ModuleError('Something went wrong during module update: ' + e.message)
ModuleError: 'Something went wrong during module update: Data not properly sent to server. Please set "file" in POST data.'
[01/Aug/2016 16:58:28] WARNING [django.request:143] Not Found: /favicon.ico
[01/Aug/2016 17:00:32] WARNING [django.request:143] Not Found: /favicon.ico
[01/Aug/2016 17:54:03] WARNING [django.request:143] Not Found: /favicon.ico
[01/Aug/2016 18:18:53] ERROR [django.request:231] Internal Server Error: /curate/save_form
Traceback (most recent call last):
  File "/home/NANOMINE/usr/local/lib/python2.7/site-packages/django/core/handlers/base.py", line 111, in get_response
    response = wrapped_callback(request, *callback_args, **callback_kwargs)
  File "/home/NANOMINE/Develop/mdcs/curate/ajax.py", line 79, in save_form
    form_data = FormData.objects.get(id=form_data_id)
  File "/home/NANOMINE/usr/local/lib/python2.7/site-packages/mongoengine/queryset/base.py", line 186, in get
    raise queryset._document.DoesNotExist(msg)
DoesNotExist: FormData matching query does not exist.
[01/Aug/2016 18:20:10] ERROR [django.request:231] Internal Server Error: /curate/view-data
Traceback (most recent call last):
  File "/home/NANOMINE/usr/local/lib/python2.7/site-packages/django/core/handlers/base.py", line 111, in get_response
    response = wrapped_callback(request, *callback_args, **callback_kwargs)
  File "/home/NANOMINE/Develop/mdcs/curate/views.py", line 165, in curate_view_data
    form_data = FormData.objects.get(pk=ObjectId(form_data_id))
  File "/home/NANOMINE/usr/local/lib/python2.7/site-packages/mongoengine/queryset/base.py", line 186, in get
    raise queryset._document.DoesNotExist(msg)
DoesNotExist: FormData matching query does not exist.
[01/Aug/2016 18:34:48] WARNING [django.request:143] Not Found: /apple-touch-icon-precomposed.png
[01/Aug/2016 18:34:48] WARNING [django.request:143] Not Found: /apple-touch-icon.png
[01/Aug/2016 18:34:48] ERROR [django.request:231] Internal Server Error: /curate/
Traceback (most recent call last):
  File "/home/NANOMINE/usr/local/lib/python2.7/site-packages/django/core/handlers/base.py", line 111, in get_response
    response = wrapped_callback(request, *callback_args, **callback_kwargs)
  File "/home/NANOMINE/Develop/mdcs/curate/views.py", line 66, in index
    return HttpResponse(template.render(context))
  File "/home/NANOMINE/usr/local/lib/python2.7/site-packages/django/template/base.py", line 148, in render
    return self._render(context)
  File "/home/NANOMINE/usr/local/lib/python2.7/site-packages/django/template/base.py", line 142, in _render
    return self.nodelist.render(context)
  File "/home/NANOMINE/usr/local/lib/python2.7/site-packages/django/template/base.py", line 844, in render
    bit = self.render_node(node, context)
  File "/home/NANOMINE/usr/local/lib/python2.7/site-packages/django/template/base.py", line 858, in render_node
    return node.render(context)
  File "/home/NANOMINE/usr/local/lib/python2.7/site-packages/django/template/loader_tags.py", line 104, in render
    compiled_parent = self.get_parent(context)
  File "/home/NANOMINE/usr/local/lib/python2.7/site-packages/django/template/loader_tags.py", line 101, in get_parent
    return get_template(parent)
  File "/home/NANOMINE/usr/local/lib/python2.7/site-packages/django/template/loader.py", line 144, in get_template
    template, origin = find_template(template_name, dirs)
  File "/home/NANOMINE/usr/local/lib/python2.7/site-packages/django/template/loader.py", line 132, in find_template
    source, display_name = loader(name, dirs)
  File "/home/NANOMINE/usr/local/lib/python2.7/site-packages/django/template/loader.py", line 44, in __call__
    return self.load_template(template_name, template_dirs)
  File "/home/NANOMINE/usr/local/lib/python2.7/site-packages/django/template/loader.py", line 50, in load_template
    template = get_template_from_string(source, origin, template_name)
  File "/home/NANOMINE/usr/local/lib/python2.7/site-packages/django/template/loader.py", line 156, in get_template_from_string
    return Template(source, origin, name)
  File "/home/NANOMINE/usr/local/lib/python2.7/site-packages/django/template/base.py", line 132, in __init__
    self.nodelist = compile_string(template_string, origin)
  File "/home/NANOMINE/usr/local/lib/python2.7/site-packages/django/template/base.py", line 162, in compile_string
    return parser.parse()
  File "/home/NANOMINE/usr/local/lib/python2.7/site-packages/django/template/base.py", line 290, in parse
    compiled_result = compile_func(self, token)
  File "/home/NANOMINE/usr/local/lib/python2.7/site-packages/django/template/loader_tags.py", line 201, in do_extends
    nodelist = parser.parse()
  File "/home/NANOMINE/usr/local/lib/python2.7/site-packages/django/template/base.py", line 290, in parse
    compiled_result = compile_func(self, token)
  File "/home/NANOMINE/usr/local/lib/python2.7/site-packages/django/template/loader_tags.py", line 175, in do_block
    nodelist = parser.parse(('endblock',))
  File "/home/NANOMINE/usr/local/lib/python2.7/site-packages/django/template/base.py", line 290, in parse
    compiled_result = compile_func(self, token)
  File "/home/NANOMINE/usr/local/lib/python2.7/site-packages/django/template/loader_tags.py", line 171, in do_block
    raise TemplateSyntaxError("'%s' tag with name '%s' appears more than once" % (bits[0], block_name))
TemplateSyntaxError: 'block' tag with name 'sidebar' appears more than once
[01/Aug/2016 18:34:49] ERROR [django.request:231] Internal Server Error: /explore/results
Traceback (most recent call last):
  File "/home/NANOMINE/usr/local/lib/python2.7/site-packages/django/core/handlers/base.py", line 111, in get_response
    response = wrapped_callback(request, *callback_args, **callback_kwargs)
  File "/home/NANOMINE/Develop/mdcs/explore/views.py", line 175, in explore_results
    return HttpResponse(template.render(context))
  File "/home/NANOMINE/usr/local/lib/python2.7/site-packages/django/template/base.py", line 148, in render
    return self._render(context)
  File "/home/NANOMINE/usr/local/lib/python2.7/site-packages/django/template/base.py", line 142, in _render
    return self.nodelist.render(context)
  File "/home/NANOMINE/usr/local/lib/python2.7/site-packages/django/template/base.py", line 844, in render
    bit = self.render_node(node, context)
  File "/home/NANOMINE/usr/local/lib/python2.7/site-packages/django/template/base.py", line 858, in render_node
    return node.render(context)
  File "/home/NANOMINE/usr/local/lib/python2.7/site-packages/django/template/loader_tags.py", line 104, in render
    compiled_parent = self.get_parent(context)
  File "/home/NANOMINE/usr/local/lib/python2.7/site-packages/django/template/loader_tags.py", line 101, in get_parent
    return get_template(parent)
  File "/home/NANOMINE/usr/local/lib/python2.7/site-packages/django/template/loader.py", line 144, in get_template
    template, origin = find_template(template_name, dirs)
  File "/home/NANOMINE/usr/local/lib/python2.7/site-packages/django/template/loader.py", line 132, in find_template
    source, display_name = loader(name, dirs)
  File "/home/NANOMINE/usr/local/lib/python2.7/site-packages/django/template/loader.py", line 44, in __call__
    return self.load_template(template_name, template_dirs)
  File "/home/NANOMINE/usr/local/lib/python2.7/site-packages/django/template/loader.py", line 50, in load_template
    template = get_template_from_string(source, origin, template_name)
  File "/home/NANOMINE/usr/local/lib/python2.7/site-packages/django/template/loader.py", line 156, in get_template_from_string
    return Template(source, origin, name)
  File "/home/NANOMINE/usr/local/lib/python2.7/site-packages/django/template/base.py", line 132, in __init__
    self.nodelist = compile_string(template_string, origin)
  File "/home/NANOMINE/usr/local/lib/python2.7/site-packages/django/template/base.py", line 162, in compile_string
    return parser.parse()
  File "/home/NANOMINE/usr/local/lib/python2.7/site-packages/django/template/base.py", line 290, in parse
    compiled_result = compile_func(self, token)
  File "/home/NANOMINE/usr/local/lib/python2.7/site-packages/django/template/loader_tags.py", line 201, in do_extends
    nodelist = parser.parse()
  File "/home/NANOMINE/usr/local/lib/python2.7/site-packages/django/template/base.py", line 290, in parse
    compiled_result = compile_func(self, token)
  File "/home/NANOMINE/usr/local/lib/python2.7/site-packages/django/template/loader_tags.py", line 175, in do_block
    nodelist = parser.parse(('endblock',))
  File "/home/NANOMINE/usr/local/lib/python2.7/site-packages/django/template/base.py", line 290, in parse
    compiled_result = compile_func(self, token)
  File "/home/NANOMINE/usr/local/lib/python2.7/site-packages/django/template/loader_tags.py", line 171, in do_block
    raise TemplateSyntaxError("'%s' tag with name '%s' appears more than once" % (bits[0], block_name))
TemplateSyntaxError: 'block' tag with name 'sidebar' appears more than once
